Workbook

Sheet Summary CC Vol
B2: Sheet Name | C2: 1 | D2: =C2+1 -> 2 | E2: =D2+1 -> 3 | F2: =E2+1 -> 4 | G2: =F2+1 -> 5 | H2: =G2+1 -> 6 | I2: =H2+1 -> 7 | J2: =I2+1 -> 8 | K2: =J2+1 -> 9 | ... AL2: =AK2+1 -> 36 | AM2: 37
A3: Category | B3: Months | C3: 44562 | D3: =EOMONTH(C3,1)-1 -> 44619 | E3: =EOMONTH(D3,1)-1 -> 44650 | F3: =EOMONTH(E3,1)-1 -> 44680 | G3: =EOMONTH(F3,1)-1 -> 44711 | H3: =EOMONTH(G3,1)-1 -> 44741 | I3: =EOMONTH(H3,1)-1 -> 44772 | J3: =EOMONTH(I3,1)-1 -> 44803 | K3: =EOMONTH(J3,1)-1 -> 44833 | ... AM3: =EOMONTH(AL3,1)-1 -> 45687 | AO3: FY 24 9M | AP3: FY 25 9 M | AT3: % distribution of Total
A4: Private Sector Banks | B4: HDFC BANK LTD | C4: =IFERROR(VLOOKUP(B4,'1'!$C$3:$S$100,8,FALSE),"") -> 16045393 | D4: =IFERROR(VLOOKUP(B4,'2'!$C$3:$S$100,8,FALSE),"") -> 16272871 | E4: =IFERROR(VLOOKUP($B4,INDIRECT("'" & E$2 & "'!$C$3:$R$100"),8,FALSE),"") -> 16536735 | F4: =IFERROR(VLOOKUP($B4,INDIRECT("'" & F$2 & "'!$C$3:$R$100"),8,FALSE),"") -> 16833724 | G4: =IFERROR(VLOOKUP($B4,INDIRECT("'" & G$2 & "'!$C$3:$R$100"),8,FALSE),"") -> 17219010 | H4: =IFERROR(VLOOKUP($B4,INDIRECT("'" & H$2 & "'!$C$3:$R$100"),8,FALSE),"") -> 17605497 | I4: =IFERROR(VLOOKUP($B4,INDIRECT("'" & I$2 & "'!$C$3:$R$100"),8,FALSE),"") -> 17949861 | J4: =IFERROR(VLOOKUP($B4,INDIRECT("'" & J$2 & "'!$C$3:$R$100"),8,FALSE),"") -> 16428971 | K4: =IFERROR(VLOOKUP($B4,INDIRECT("'" & K$2 & "'!$C$3:$R$100"),8,FALSE),"") -> 16328522 | L4: =IFERROR(VLOOKUP($B4,INDIRECT("'" & L$2 & "'!$C$3:$R$100"),8,FALSE),"") -> 16546501 | ... AM4: =IFERROR(VLOOKUP($B4,INDIRECT("'" & AM$2 & "'!$C$3:$R$100"),8,FALSE),"") -> 23444799 | AN4: =AL4/SUM($AL$4:$AL$68) -> 0.21419503 | AO4: =Z4/R4-1 -> 0.11181319 | AP4: =AL4/AD4-1 -> 0.1115584 | AT4: =IFERROR(AJ4/$AJ$69,"") -> 0.21186622
A5: Scheduled Commercial Banks | B5: STATE BANK OF INDIA | C5: =IFERROR(VLOOKUP(B5,'1'!$C$3:$S$100,8,FALSE),"") -> 13312608 | D5: =IFERROR(VLOOKUP(B5,'2'!$C$3:$S$100,8,FALSE),"") -> 13521728 | E5: =IFERROR(VLOOKUP($B5,INDIRECT("'" & E$2 & "'!$C$3:$R$100"),8,FALSE),"") -> 13766861 | F5: =IFERROR(VLOOKUP($B5,INDIRECT("'" & F$2 & "'!$C$3:$R$100"),8,FALSE),"") -> 13946540 | G5: =IFERROR(VLOOKUP($B5,INDIRECT("'" & G$2 & "'!$C$3:$R$100"),8,FALSE),"") -> 14148758 | H5: =IFERROR(VLOOKUP($B5,INDIRECT("'" & H$2 & "'!$C$3:$R$100"),8,FALSE),"") -> 14315734 | I5: =IFERROR(VLOOKUP($B5,INDIRECT("'" & I$2 & "'!$C$3:$R$100"),8,FALSE),"") -> 14534667 | J5: =IFERROR(VLOOKUP($B5,INDIRECT("'" & J$2 & "'!$C$3:$R$100"),8,FALSE),"") -> 14830926 | K5: =IFERROR(VLOOKUP($B5,INDIRECT("'" & K$2 & "'!$C$3:$R$100"),8,FALSE),"") -> 14828035 | L5: =IFERROR(VLOOKUP($B5,INDIRECT("'" & L$2 & "'!$C$3:$R$100"),8,FALSE),"") -> 15167195 | ... AM5: =IFERROR(VLOOKUP($B5,INDIRECT("'" & AM$2 & "'!$C$3:$R$100"),8,FALSE),"") -> 20481479 | AN5: =AL5/SUM($AL$4:$AL$68) -> 0.18737469 | AO5: =Z5/R5-1 -> 0.096100556 | AP5: =AL5/AD5-1 -> 0.065426824 | AT5: =IFERROR(AJ5/$AJ$69,"") -> 0.18530464
A6: Private Sector Banks | B6: ICICI BANK LTD | C6: =IFERROR(VLOOKUP(B6,'1'!$C$3:$S$100,8,FALSE),"") -> 12595116 | D6: =IFERROR(VLOOKUP(B6,'2'!$C$3:$S$100,8,FALSE),"") -> 12773465 | E6: =IFERROR(VLOOKUP($B6,INDIRECT("'" & E$2 & "'!$C$3:$R$100"),8,FALSE),"") -> 12978825 | F6: =IFERROR(VLOOKUP($B6,INDIRECT("'" & F$2 & "'!$C$3:$R$100"),8,FALSE),"") -> 13128334 | G6: =IFERROR(VLOOKUP($B6,INDIRECT("'" & G$2 & "'!$C$3:$R$100"),8,FALSE),"") -> 13340781 | H6: =IFERROR(VLOOKUP($B6,INDIRECT("'" & H$2 & "'!$C$3:$R$100"),8,FALSE),"") -> 13531271 | I6: =IFERROR(VLOOKUP($B6,INDIRECT("'" & I$2 & "'!$C$3:$R$100"),8,FALSE),"") -> 13725493 | J6: =IFERROR(VLOOKUP($B6,INDIRECT("'" & J$2 & "'!$C$3:$R$100"),8,FALSE),"") -> 13937013 | K6: =IFERROR(VLOOKUP($B6,INDIRECT("'" & K$2 & "'!$C$3:$R$100"),8,FALSE),"") -> 13316346 | L6: =IFERROR(VLOOKUP($B6,INDIRECT("'" & L$2 & "'!$C$3:$R$100"),8,FALSE),"") -> 13537626 | ... AM6: =IFERROR(VLOOKUP($B6,INDIRECT("'" & AM$2 & "'!$C$3:$R$100"),8,FALSE),"") -> 18084209 | AN6: =AL6/SUM($AL$4:$AL$68) -> 0.16566473 | AO6: =Z6/R6-1 -> 0.13084782 | AP6: =AL6/AD6-1 -> 0.052492847 | AT6: =IFERROR(AJ6/$AJ$69,"") -> 0.16559835
A7: Private Sector Banks | B7: AXIS BANK LTD | C7: =IFERROR(VLOOKUP(B7,'1'!$C$3:$S$100,8,FALSE),"") -> 8353076 | D7: =IFERROR(VLOOKUP(B7,'2'!$C$3:$S$100,8,FALSE),"") -> 8600863 | E7: =IFERROR(VLOOKUP($B7,INDIRECT("'" & E$2 & "'!$C$3:$R$100"),8,FALSE),"") -> 9034829 | F7: =IFERROR(VLOOKUP($B7,INDIRECT("'" & F$2 & "'!$C$3:$R$100"),8,FALSE),"") -> 9261251 | G7: =IFERROR(VLOOKUP($B7,INDIRECT("'" & G$2 & "'!$C$3:$R$100"),8,FALSE),"") -> 9475786 | H7: =IFERROR(VLOOKUP($B7,INDIRECT("'" & H$2 & "'!$C$3:$R$100"),8,FALSE),"") -> 9704719 | I7: =IFERROR(VLOOKUP($B7,INDIRECT("'" & I$2 & "'!$C$3:$R$100"),8,FALSE),"") -> 9932333 | J7: =IFERROR(VLOOKUP($B7,INDIRECT("'" & J$2 & "'!$C$3:$R$100"),8,FALSE),"") -> 8879353 | K7: =IFERROR(VLOOKUP($B7,INDIRECT("'" & K$2 & "'!$C$3:$R$100"),8,FALSE),"") -> 8824819 | L7: =IFERROR(VLOOKUP($B7,INDIRECT("'" & L$2 & "'!$C$3:$R$100"),8,FALSE),"") -> 9086186 | ... AM7: =IFERROR(VLOOKUP($B7,INDIRECT("'" & AM$2 & "'!$C$3:$R$100"),8,FALSE),"") -> 14782101 | AN7: =AL7/SUM($AL$4:$AL$68) -> 0.13693803 | AO7: =Z7/R7-1 -> 0.10693579 | AP7: =AL7/AD7-1 -> 0.040319823 | AT7: =IFERROR(AJ7/$AJ$69,"") -> 0.13819535
A8: Private Sector Banks | B8: RBL BANK LTD | C8: =IFERROR(VLOOKUP(B8,'1'!$C$3:$S$100,8,FALSE),"") -> 3556159 | D8: =IFERROR(VLOOKUP(B8,'2'!$C$3:$S$100,8,FALSE),"") -> 3631509 | E8: =IFERROR(VLOOKUP($B8,INDIRECT("'" & E$2 & "'!$C$3:$R$100"),8,FALSE),"") -> 3682603 | F8: =IFERROR(VLOOKUP($B8,INDIRECT("'" & F$2 & "'!$C$3:$R$100"),8,FALSE),"") -> 3754269 | G8: =IFERROR(VLOOKUP($B8,INDIRECT("'" & G$2 & "'!$C$3:$R$100"),8,FALSE),"") -> 3827746 | H8: =IFERROR(VLOOKUP($B8,INDIRECT("'" & H$2 & "'!$C$3:$R$100"),8,FALSE),"") -> 3914742 | I8: =IFERROR(VLOOKUP($B8,INDIRECT("'" & I$2 & "'!$C$3:$R$100"),8,FALSE),"") -> 4005255 | J8: =IFERROR(VLOOKUP($B8,INDIRECT("'" & J$2 & "'!$C$3:$R$100"),8,FALSE),"") -> 4044789 | K8: =IFERROR(VLOOKUP($B8,INDIRECT("'" & K$2 & "'!$C$3:$R$100"),8,FALSE),"") -> 4097800 | L8: =IFERROR(VLOOKUP($B8,INDIRECT("'" & L$2 & "'!$C$3:$R$100"),8,FALSE),"") -> 4166704 | ... AM8: =IFERROR(VLOOKUP($B8,INDIRECT("'" & AM$2 & "'!$C$3:$R$100"),8,FALSE),"") -> 4973507 | AN8: =AL8/SUM($AL$4:$AL$68) -> 0.046628086 | AO8: =Z8/R8-1 -> 0.11343882 | AP8: =AL8/AD8-1 -> -0.033780776 | AT8: =IFERROR(AJ8/$AJ$69,"") -> 0.048409025
A9: Private Sector Banks | B9: KOTAK MAHINDRA BANK LTD | C9: =IFERROR(VLOOKUP(B9,'1'!$C$3:$S$100,8,FALSE),"") -> 2877676 | D9: =IFERROR(VLOOKUP(B9,'2'!$C$3:$S$100,8,FALSE),"") -> 3034474 | E9: =IFERROR(VLOOKUP($B9,INDIRECT("'" & E$2 & "'!$C$3:$R$100"),8,FALSE),"") -> 3196377 | F9: =IFERROR(VLOOKUP($B9,INDIRECT("'" & F$2 & "'!$C$3:$R$100"),8,FALSE),"") -> 3425409 | G9: =IFERROR(VLOOKUP($B9,INDIRECT("'" & G$2 & "'!$C$3:$R$100"),8,FALSE),"") -> 3606571 | H9: =IFERROR(VLOOKUP($B9,INDIRECT("'" & H$2 & "'!$C$3:$R$100"),8,FALSE),"") -> 3869513 | I9: =IFERROR(VLOOKUP($B9,INDIRECT("'" & I$2 & "'!$C$3:$R$100"),8,FALSE),"") -> 4052093 | J9: =IFERROR(VLOOKUP($B9,INDIRECT("'" & J$2 & "'!$C$3:$R$100"),8,FALSE),"") -> 4107595 | K9: =IFERROR(VLOOKUP($B9,INDIRECT("'" & K$2 & "'!$C$3:$R$100"),8,FALSE),"") -> 4299906 | L9: =IFERROR(VLOOKUP($B9,INDIRECT("'" & L$2 & "'!$C$3:$R$100"),8,FALSE),"") -> 4519524 | ... AM9: =IFERROR(VLOOKUP($B9,INDIRECT("'" & AM$2 & "'!$C$3:$R$100"),8,FALSE),"") -> 4995388 | AN9: =AL9/SUM($AL$4:$AL$68) -> 0.046472361 | AO9: =Z9/R9-1 -> 0.15022129 | AP9: =AL9/AD9-1 -> -0.16313047 | AT9: =IFERROR(AJ9/$AJ$69,"") -> 0.04871478
A10: Private Sector Banks | B10: IDFC FIRST BANK LTD | C10: =IFERROR(VLOOKUP(B10,'1'!$C$3:$S$100,8,FALSE),"") -> 685934 | D10: =IFERROR(VLOOKUP(B10,'2'!$C$3:$S$100,8,FALSE),"") -> 739541 | E10: =IFERROR(VLOOKUP($B10,INDIRECT("'" & E$2 & "'!$C$3:$R$100"),8,FALSE),"") -> 799219 | F10: =IFERROR(VLOOKUP($B10,INDIRECT("'" & F$2 & "'!$C$3:$R$100"),8,FALSE),"") -> 856394 | G10: =IFERROR(VLOOKUP($B10,INDIRECT("'" & G$2 & "'!$C$3:$R$100"),8,FALSE),"") -> 887837 | H10: =IFERROR(VLOOKUP($B10,INDIRECT("'" & H$2 & "'!$C$3:$R$100"),8,FALSE),"") -> 962792 | I10: =IFERROR(VLOOKUP($B10,INDIRECT("'" & I$2 & "'!$C$3:$R$100"),8,FALSE),"") -> 1042747 | J10: =IFERROR(VLOOKUP($B10,INDIRECT("'" & J$2 & "'!$C$3:$R$100"),8,FALSE),"") -> 1113545 | K10: =IFERROR(VLOOKUP($B10,INDIRECT("'" & K$2 & "'!$C$3:$R$100"),8,FALSE),"") -> 1204190 | L10: =IFERROR(VLOOKUP($B10,INDIRECT("'" & L$2 & "'!$C$3:$R$100"),8,FALSE),"") -> 1269278 | ... AM10: =IFERROR(VLOOKUP($B10,INDIRECT("'" & AM$2 & "'!$C$3:$R$100"),8,FALSE),"") -> 3388080 | AN10: =AL10/SUM($AL$4:$AL$68) -> 0.03046386 | AO10: =Z10/R10-1 -> 0.42450191 | AP10: =AL10/AD10-1 -> 0.2402193 | AT10: =IFERROR(AJ10/$AJ$69,"") -> 0.029431464
A11: Private Sector Banks | B11: INDUSIND BANK LTD | C11: =IFERROR(VLOOKUP(B11,'1'!$C$3:$S$100,8,FALSE),"") -> 1788984 | D11: =IFERROR(VLOOKUP(B11,'2'!$C$3:$S$100,8,FALSE),"") -> 1837032 | E11: =IFERROR(VLOOKUP($B11,INDIRECT("'" & E$2 & "'!$C$3:$R$100"),8,FALSE),"") -> 1880393 | F11: =IFERROR(VLOOKUP($B11,INDIRECT("'" & F$2 & "'!$C$3:$R$100"),8,FALSE),"") -> 1922608 | G11: =IFERROR(VLOOKUP($B11,INDIRECT("'" & G$2 & "'!$C$3:$R$100"),8,FALSE),"") -> 1972365 | H11: =IFERROR(VLOOKUP($B11,INDIRECT("'" & H$2 & "'!$C$3:$R$100"),8,FALSE),"") -> 2029218 | I11: =IFERROR(VLOOKUP($B11,INDIRECT("'" & I$2 & "'!$C$3:$R$100"),8,FALSE),"") -> 1822569 | J11: =IFERROR(VLOOKUP($B11,INDIRECT("'" & J$2 & "'!$C$3:$R$100"),8,FALSE),"") -> 1869104 | K11: =IFERROR(VLOOKUP($B11,INDIRECT("'" & K$2 & "'!$C$3:$R$100"),8,FALSE),"") -> 1931403 | L11: =IFERROR(VLOOKUP($B11,INDIRECT("'" & L$2 & "'!$C$3:$R$100"),8,FALSE),"") -> 1964481 | ... AM11: =IFERROR(VLOOKUP($B11,INDIRECT("'" & AM$2 & "'!$C$3:$R$100"),8,FALSE),"") -> 3152176 | AN11: =AL11/SUM($AL$4:$AL$68) -> 0.028849631 | AO11: =Z11/R11-1 -> 0.20216132 | AP11: =AL11/AD11-1 -> 0.06150836 | AT11: =IFERROR(AJ11/$AJ$69,"") -> 0.028576161
A12: Scheduled Commercial Banks | B12: BANK OF BARODA | C12: =IFERROR(VLOOKUP(B12,'1'!$C$3:$S$100,8,FALSE),"") -> 862290 | D12: =IFERROR(VLOOKUP(B12,'2'!$C$3:$S$100,8,FALSE),"") -> 945037 | E12: =IFERROR(VLOOKUP($B12,INDIRECT("'" & E$2 & "'!$C$3:$R$100"),8,FALSE),"") -> 1103921 | F12: =IFERROR(VLOOKUP($B12,INDIRECT("'" & F$2 & "'!$C$3:$R$100"),8,FALSE),"") -> 1194104 | G12: =IFERROR(VLOOKUP($B12,INDIRECT("'" & G$2 & "'!$C$3:$R$100"),8,FALSE),"") -> 1267896 | H12: =IFERROR(VLOOKUP($B12,INDIRECT("'" & H$2 & "'!$C$3:$R$100"),8,FALSE),"") -> 1348264 | I12: =IFERROR(VLOOKUP($B12,INDIRECT("'" & I$2 & "'!$C$3:$R$100"),8,FALSE),"") -> 1416927 | J12: =IFERROR(VLOOKUP($B12,INDIRECT("'" & J$2 & "'!$C$3:$R$100"),8,FALSE),"") -> 1428072 | K12: =IFERROR(VLOOKUP($B12,INDIRECT("'" & K$2 & "'!$C$3:$R$100"),8,FALSE),"") -> 1502964 | L12: =IFERROR(VLOOKUP($B12,INDIRECT("'" & L$2 & "'!$C$3:$R$100"),8,FALSE),"") -> 1578148 | ... AM12: =IFERROR(VLOOKUP($B12,INDIRECT("'" & AM$2 & "'!$C$3:$R$100"),8,FALSE),"") -> 2936005 | AN12: =AL12/SUM($AL$4:$AL$68) -> 0.027188667 | AO12: =Z12/R12-1 -> 0.15346007 | AP12: =AL12/AD12-1 -> 0.15036932 | AT12: =IFERROR(AJ12/$AJ$69,"") -> 0.026938444
A13: Private Sector Banks | B13: YES BANK LTD | C13: =IFERROR(VLOOKUP(B13,'1'!$C$3:$S$100,8,FALSE),"") -> 1105401 | D13: =IFERROR(VLOOKUP(B13,'2'!$C$3:$S$100,8,FALSE),"") -> 1144367 | E13: =IFERROR(VLOOKUP($B13,INDIRECT("'" & E$2 & "'!$C$3:$R$100"),8,FALSE),"") -> 1184542 | F13: =IFERROR(VLOOKUP($B13,INDIRECT("'" & F$2 & "'!$C$3:$R$100"),8,FALSE),"") -> 1209178 | G13: =IFERROR(VLOOKUP($B13,INDIRECT("'" & G$2 & "'!$C$3:$R$100"),8,FALSE),"") -> 1238367 | H13: =IFERROR(VLOOKUP($B13,INDIRECT("'" & H$2 & "'!$C$3:$R$100"),8,FALSE),"") -> 1294496 | I13: =IFERROR(VLOOKUP($B13,INDIRECT("'" & I$2 & "'!$C$3:$R$100"),8,FALSE),"") -> 1331990 | J13: =IFERROR(VLOOKUP($B13,INDIRECT("'" & J$2 & "'!$C$3:$R$100"),8,FALSE),"") -> 1246243 | K13: =IFERROR(VLOOKUP($B13,INDIRECT("'" & K$2 & "'!$C$3:$R$100"),8,FALSE),"") -> 1291423 | L13: =IFERROR(VLOOKUP($B13,INDIRECT("'" & L$2 & "'!$C$3:$R$100"),8,FALSE),"") -> 1327942 | ... AM13: =IFERROR(VLOOKUP($B13,INDIRECT("'" & AM$2 & "'!$C$3:$R$100"),8,FALSE),"") -> 2410672 | AN13: =AL13/SUM($AL$4:$AL$68) -> 0.022284243 | AO13: =Z13/R13-1 -> 0.25121422 | AP13: =AL13/AD13-1 -> 0.14054839 | AT13: =IFERROR(AJ13/$AJ$69,"") -> 0.021910203
A14: Foreign Banks | B14: AMERICAN EXPRESS BANKING CORPORATION | C14: =IFERROR(VLOOKUP(B14,'1'!$C$3:$S$100,8,FALSE),"") -> 1405362 | D14: =IFERROR(VLOOKUP(B14,'2'!$C$3:$S$100,8,FALSE),"") -> 1393728 | E14: =IFERROR(VLOOKUP($B14,INDIRECT("'" & E$2 & "'!$C$3:$R$100"),8,FALSE),"") -> 1383221 | F14: =IFERROR(VLOOKUP($B14,INDIRECT("'" & F$2 & "'!$C$3:$R$100"),8,FALSE),"") -> 1375307 | G14: =IFERROR(VLOOKUP($B14,INDIRECT("'" & G$2 & "'!$C$3:$R$100"),8,FALSE),"") -> 1366552 | H14: =IFERROR(VLOOKUP($B14,INDIRECT("'" & H$2 & "'!$C$3:$R$100"),8,FALSE),"") -> 1360776 | I14: =IFERROR(VLOOKUP($B14,INDIRECT("'" & I$2 & "'!$C$3:$R$100"),8,FALSE),"") -> 1356420 | J14: =IFERROR(VLOOKUP($B14,INDIRECT("'" & J$2 & "'!$C$3:$R$100"),8,FALSE),"") -> 1353402 | K14: =IFERROR(VLOOKUP($B14,INDIRECT("'" & K$2 & "'!$C$3:$R$100"),8,FALSE),"") -> 1299223 | L14: =IFERROR(VLOOKUP($B14,INDIRECT("'" & L$2 & "'!$C$3:$R$100"),8,FALSE),"") -> 1304696 | ... AM14: =IFERROR(VLOOKUP($B14,INDIRECT("'" & AM$2 & "'!$C$3:$R$100"),8,FALSE),"") -> 1453258 | AN14: =AL14/SUM($AL$4:$AL$68) -> 0.01330328 | AO14: =Z14/R14-1 -> 0.011136277 | AP14: =AL14/AD14-1 -> 0.061644913 | AT14: =IFERROR(AJ14/$AJ$69,"") -> 0.013377497
A15: Private Sector Banks | B15: FEDERAL BANK LTD | C15: =IFERROR(VLOOKUP(B15,'1'!$C$3:$S$100,8,FALSE),"") -> 87536 | D15: =IFERROR(VLOOKUP(B15,'2'!$C$3:$S$100,8,FALSE),"") -> 104232 | E15: =IFERROR(VLOOKUP($B15,INDIRECT("'" & E$2 & "'!$C$3:$R$100"),8,FALSE),"") -> 134841 | F15: =IFERROR(VLOOKUP($B15,INDIRECT("'" & F$2 & "'!$C$3:$R$100"),8,FALSE),"") -> 170251 | G15: =IFERROR(VLOOKUP($B15,INDIRECT("'" & G$2 & "'!$C$3:$R$100"),8,FALSE),"") -> 205091 | H15: =IFERROR(VLOOKUP($B15,INDIRECT("'" & H$2 & "'!$C$3:$R$100"),8,FALSE),"") -> 234580 | I15: =IFERROR(VLOOKUP($B15,INDIRECT("'" & I$2 & "'!$C$3:$R$100"),8,FALSE),"") -> 264497 | J15: =IFERROR(VLOOKUP($B15,INDIRECT("'" & J$2 & "'!$C$3:$R$100"),8,FALSE),"") -> 297437 | K15: =IFERROR(VLOOKUP($B15,INDIRECT("'" & K$2 & "'!$C$3:$R$100"),8,FALSE),"") -> 332823 | L15: =IFERROR(VLOOKUP($B15,INDIRECT("'" & L$2 & "'!$C$3:$R$100"),8,FALSE),"") -> 370543 | ... AM15: =IFERROR(VLOOKUP($B15,INDIRECT("'" & AM$2 & "'!$C$3:$R$100"),8,FALSE),"") -> 1120269 | AN15: =AL15/SUM($AL$4:$AL$68) -> 0.010134819 | AO15: =Z15/R15-1 -> 0.55724176 | AP15: =AL15/AD15-1 -> 0.12914707 | AT15: =IFERROR(AJ15/$AJ$69,"") -> 0.009921222
... A41: Small Finance Banks | B41: EQUITAS SMALL FINANCE BANK LTD | C41: =IFERROR(VLOOKUP(B41,'1'!$C$3:$S$100,8,FALSE),"") -> 0 | D41: =IFERROR(VLOOKUP(B41,'2'!$C$3:$S$100,8,FALSE),"") -> 0 | E41: =IFERROR(VLOOKUP($B41,INDIRECT("'" & E$2 & "'!$C$3:$R$100"),8,FALSE),"") -> 0 | F41: =IFERROR(VLOOKUP($B41,INDIRECT("'" & F$2 & "'!$C$3:$R$100"),8,FALSE),"") -> 0 | G41: =IFERROR(VLOOKUP($B41,INDIRECT("'" & G$2 & "'!$C$3:$R$100"),8,FALSE),"") -> 0 | H41: =IFERROR(VLOOKUP($B41,INDIRECT("'" & H$2 & "'!$C$3:$R$100"),8,FALSE),"") -> 0 | I41: =IFERROR(VLOOKUP($B41,INDIRECT("'" & I$2 & "'!$C$3:$R$100"),8,FALSE),"") -> 0 | J41: =IFERROR(VLOOKUP($B41,INDIRECT("'" & J$2 & "'!$C$3:$R$100"),8,FALSE),"") -> 0 | K41: =IFERROR(VLOOKUP($B41,INDIRECT("'" & K$2 & "'!$C$3:$R$100"),8,FALSE),"") -> 0 | L41: =IFERROR(VLOOKUP($B41,INDIRECT("'" & L$2 & "'!$C$3:$R$100"),8,FALSE),"") -> 0 | ... AM41: =IFERROR(VLOOKUP($B41,INDIRECT("'" & AM$2 & "'!$C$3:$R$100"),8,FALSE),"") -> 65 | AN41: =AL41/SUM($AL$4:$AL$68) -> 1.0179916e-07 | AO41: =Z41/R41-1 -> #DIV/0! | AP41: =AL41/AD41-1 -> #DIV/0! | AT41: =IFERROR(AJ41/$AJ$69,"") -> 0
A42: Small Finance Banks | B42: FINCARE SMALL FINANCE BANK LIMITED | C42: =IFERROR(VLOOKUP(B42,'1'!$C$3:$S$100,8,FALSE),0) -> 0 | D42: =IFERROR(VLOOKUP(C42,'1'!$C$3:$S$100,8,FALSE),0) -> 0 | E42: =IFERROR(VLOOKUP(D42,'1'!$C$3:$S$100,8,FALSE),0) -> 0 | F42: =IFERROR(VLOOKUP(E42,'1'!$C$3:$S$100,8,FALSE),0) -> 0 | G42: =IFERROR(VLOOKUP(F42,'1'!$C$3:$S$100,8,FALSE),0) -> 0 | H42: =IFERROR(VLOOKUP(G42,'1'!$C$3:$S$100,8,FALSE),0) -> 0 | I42: =IFERROR(VLOOKUP(H42,'1'!$C$3:$S$100,8,FALSE),0) -> 0 | J42: =IFERROR(VLOOKUP(I42,'1'!$C$3:$S$100,8,FALSE),0) -> 0 | ... AM42: =IFERROR(VLOOKUP(AL42,'1'!$C$3:$S$100,8,FALSE),0) -> 0 | AN42: =AL42/SUM($AL$4:$AL$68) -> 0 | AO42: =Z42/R42-1 -> #DIV/0! | AP42: =AL42/AD42-1 -> #DIV/0! | AT42: =IFERROR(AJ42/$AJ$69,"") -> 0
A43: Scheduled Commercial Banks | B43: CENTRAL BANK OF INDIA | C43: =IFERROR(VLOOKUP(B43,'1'!$C$3:$S$100,8,FALSE),"") -> 0 | D43: =IFERROR(VLOOKUP(B43,'2'!$C$3:$S$100,8,FALSE),"") -> 0 | E43: =IFERROR(VLOOKUP($B43,INDIRECT("'" & E$2 & "'!$C$3:$R$100"),8,FALSE),"") -> 0 | F43: =IFERROR(VLOOKUP($B43,INDIRECT("'" & F$2 & "'!$C$3:$R$100"),8,FALSE),"") -> 0 | G43: =IFERROR(VLOOKUP($B43,INDIRECT("'" & G$2 & "'!$C$3:$R$100"),8,FALSE),"") -> 0 | H43: =IFERROR(VLOOKUP($B43,INDIRECT("'" & H$2 & "'!$C$3:$R$100"),8,FALSE),"") -> 0 | I43: =IFERROR(VLOOKUP($B43,INDIRECT("'" & I$2 & "'!$C$3:$R$100"),8,FALSE),"") -> 0 | J43: =IFERROR(VLOOKUP($B43,INDIRECT("'" & J$2 & "'!$C$3:$R$100"),8,FALSE),"") -> 0 | K43: =IFERROR(VLOOKUP($B43,INDIRECT("'" & K$2 & "'!$C$3:$R$100"),8,FALSE),"") -> 0 | L43: =IFERROR(VLOOKUP($B43,INDIRECT("'" & L$2 & "'!$C$3:$R$100"),8,FALSE),"") -> 0 | ... AM43: =IFERROR(VLOOKUP($B43,INDIRECT("'" & AM$2 & "'!$C$3:$R$100"),8,FALSE),"") -> 0 | AN43: =AL43/SUM($AL$4:$AL$68) -> 0 | AO43: =Z43/R43-1 -> #DIV/0! | AP43: =AL43/AD43-1 -> #DIV/0! | AT43: =IFERROR(AJ43/$AJ$69,"") -> 0
A44: Scheduled Commercial Banks | B44: PUNJAB AND SIND BANK | C44: =IFERROR(VLOOKUP(B44,'1'!$C$3:$S$100,8,FALSE),"") -> 0 | D44: =IFERROR(VLOOKUP(B44,'2'!$C$3:$S$100,8,FALSE),"") -> 0 | E44: =IFERROR(VLOOKUP($B44,INDIRECT("'" & E$2 & "'!$C$3:$R$100"),8,FALSE),"") -> 0 | F44: =IFERROR(VLOOKUP($B44,INDIRECT("'" & F$2 & "'!$C$3:$R$100"),8,FALSE),"") -> 0 | G44: =IFERROR(VLOOKUP($B44,INDIRECT("'" & G$2 & "'!$C$3:$R$100"),8,FALSE),"") -> 0 | H44: =IFERROR(VLOOKUP($B44,INDIRECT("'" & H$2 & "'!$C$3:$R$100"),8,FALSE),"") -> 0 | I44: =IFERROR(VLOOKUP($B44,INDIRECT("'" & I$2 & "'!$C$3:$R$100"),8,FALSE),"") -> 0 | J44: =IFERROR(VLOOKUP($B44,INDIRECT("'" & J$2 & "'!$C$3:$R$100"),8,FALSE),"") -> 0 | K44: =IFERROR(VLOOKUP($B44,INDIRECT("'" & K$2 & "'!$C$3:$R$100"),8,FALSE),"") -> 0 | L44: =IFERROR(VLOOKUP($B44,INDIRECT("'" & L$2 & "'!$C$3:$R$100"),8,FALSE),"") -> 0 | ... AM44: =IFERROR(VLOOKUP($B44,INDIRECT("'" & AM$2 & "'!$C$3:$R$100"),8,FALSE),"") -> 0 | AN44: =AL44/SUM($AL$4:$AL$68) -> 0 | AO44: =Z44/R44-1 -> #DIV/0! | AP44: =AL44/AD44-1 -> #DIV/0! | AT44: =IFERROR(AJ44/$AJ$69,"") -> 0
A45: Scheduled Commercial Banks | B45: UCO BANK | C45: =IFERROR(VLOOKUP(B45,'1'!$C$3:$S$100,8,FALSE),"") -> 0 | D45: =IFERROR(VLOOKUP(B45,'2'!$C$3:$S$100,8,FALSE),"") -> 0 | E45: =IFERROR(VLOOKUP($B45,INDIRECT("'" & E$2 & "'!$C$3:$R$100"),8,FALSE),"") -> 0 | F45: =IFERROR(VLOOKUP($B45,INDIRECT("'" & F$2 & "'!$C$3:$R$100"),8,FALSE),"") -> 0 | G45: =IFERROR(VLOOKUP($B45,INDIRECT("'" & G$2 & "'!$C$3:$R$100"),8,FALSE),"") -> 0 | H45: =IFERROR(VLOOKUP($B45,INDIRECT("'" & H$2 & "'!$C$3:$R$100"),8,FALSE),"") -> 0 | I45: =IFERROR(VLOOKUP($B45,INDIRECT("'" & I$2 & "'!$C$3:$R$100"),8,FALSE),"") -> 0 | J45: =IFERROR(VLOOKUP($B45,INDIRECT("'" & J$2 & "'!$C$3:$R$100"),8,FALSE),"") -> 0 | K45: =IFERROR(VLOOKUP($B45,INDIRECT("'" & K$2 & "'!$C$3:$R$100"),8,FALSE),"") -> 0 | L45: =IFERROR(VLOOKUP($B45,INDIRECT("'" & L$2 & "'!$C$3:$R$100"),8,FALSE),"") -> 0 | ... AM45: =IFERROR(VLOOKUP($B45,INDIRECT("'" & AM$2 & "'!$C$3:$R$100"),8,FALSE),"") -> 0 | AN45: =AL45/SUM($AL$4:$AL$68) -> 0 | AO45: =Z45/R45-1 -> #DIV/0! | AP45: =AL45/AD45-1 -> #DIV/0! | AT45: =IFERROR(AJ45/$AJ$69,"") -> 0
A46: Private Sector Banks | B46: BANDHAN BANK LTD | C46: =IFERROR(VLOOKUP(B46,'1'!$C$3:$S$100,8,FALSE),"") -> 0 | D46: =IFERROR(VLOOKUP(B46,'2'!$C$3:$S$100,8,FALSE),"") -> 0 | E46: =IFERROR(VLOOKUP($B46,INDIRECT("'" & E$2 & "'!$C$3:$R$100"),8,FALSE),"") -> 0 | F46: =IFERROR(VLOOKUP($B46,INDIRECT("'" & F$2 & "'!$C$3:$R$100"),8,FALSE),"") -> 0 | G46: =IFERROR(VLOOKUP($B46,INDIRECT("'" & G$2 & "'!$C$3:$R$100"),8,FALSE),"") -> 0 | H46: =IFERROR(VLOOKUP($B46,INDIRECT("'" & H$2 & "'!$C$3:$R$100"),8,FALSE),"") -> 0 | I46: =IFERROR(VLOOKUP($B46,INDIRECT("'" & I$2 & "'!$C$3:$R$100"),8,FALSE),"") -> 0 | J46: =IFERROR(VLOOKUP($B46,INDIRECT("'" & J$2 & "'!$C$3:$R$100"),8,FALSE),"") -> 0 | K46: =IFERROR(VLOOKUP($B46,INDIRECT("'" & K$2 & "'!$C$3:$R$100"),8,FALSE),"") -> 0 | L46: =IFERROR(VLOOKUP($B46,INDIRECT("'" & L$2 & "'!$C$3:$R$100"),8,FALSE),"") -> 0 | ... AM46: =IFERROR(VLOOKUP($B46,INDIRECT("'" & AM$2 & "'!$C$3:$R$100"),8,FALSE),"") -> 0 | AN46: =AL46/SUM($AL$4:$AL$68) -> 0 | AO46: =Z46/R46-1 -> #DIV/0! | AP46: =AL46/AD46-1 -> -1 | AT46: =IFERROR(AJ46/$AJ$69,"") -> 0
A47: Private Sector Banks | B47: KARNATAKA BANK LTD | C47: =IFERROR(VLOOKUP(B47,'1'!$C$3:$S$100,8,FALSE),"") -> 0 | D47: =IFERROR(VLOOKUP(B47,'2'!$C$3:$S$100,8,FALSE),"") -> 0 | E47: =IFERROR(VLOOKUP($B47,INDIRECT("'" & E$2 & "'!$C$3:$R$100"),8,FALSE),"") -> 0 | F47: =IFERROR(VLOOKUP($B47,INDIRECT("'" & F$2 & "'!$C$3:$R$100"),8,FALSE),"") -> 0 | G47: =IFERROR(VLOOKUP($B47,INDIRECT("'" & G$2 & "'!$C$3:$R$100"),8,FALSE),"") -> 0 | H47: =IFERROR(VLOOKUP($B47,INDIRECT("'" & H$2 & "'!$C$3:$R$100"),8,FALSE),"") -> 0 | I47: =IFERROR(VLOOKUP($B47,INDIRECT("'" & I$2 & "'!$C$3:$R$100"),8,FALSE),"") -> 0 | J47: =IFERROR(VLOOKUP($B47,INDIRECT("'" & J$2 & "'!$C$3:$R$100"),8,FALSE),"") -> 0 | K47: =IFERROR(VLOOKUP($B47,INDIRECT("'" & K$2 & "'!$C$3:$R$100"),8,FALSE),"") -> 0 | L47: =IFERROR(VLOOKUP($B47,INDIRECT("'" & L$2 & "'!$C$3:$R$100"),8,FALSE),"") -> 0 | ... AM47: =IFERROR(VLOOKUP($B47,INDIRECT("'" & AM$2 & "'!$C$3:$R$100"),8,FALSE),"") -> 0 | AN47: =AL47/SUM($AL$4:$AL$68) -> 0 | AO47: =Z47/R47-1 -> #DIV/0! | AP47: =AL47/AD47-1 -> #DIV/0! | AT47: =IFERROR(AJ47/$AJ$69,"") -> 0
A48: Private Sector Banks | B48: NAINITAL BANK LTD | C48: =IFERROR(VLOOKUP(B48,'1'!$C$3:$S$100,8,FALSE),"") | D48: =IFERROR(VLOOKUP(B48,'2'!$C$3:$S$100,8,FALSE),"") | E48: =IFERROR(VLOOKUP($B48,INDIRECT("'" & E$2 & "'!$C$3:$R$100"),8,FALSE),"") | F48: =IFERROR(VLOOKUP($B48,INDIRECT("'" & F$2 & "'!$C$3:$R$100"),8,FALSE),"") | G48: =IFERROR(VLOOKUP($B48,INDIRECT("'" & G$2 & "'!$C$3:$R$100"),8,FALSE),"") | H48: =IFERROR(VLOOKUP($B48,INDIRECT("'" & H$2 & "'!$C$3:$R$100"),8,FALSE),"") | I48: =IFERROR(VLOOKUP($B48,INDIRECT("'" & I$2 & "'!$C$3:$R$100"),8,FALSE),"") | J48: =IFERROR(VLOOKUP($B48,INDIRECT("'" & J$2 & "'!$C$3:$R$100"),8,FALSE),"") | K48: =IFERROR(VLOOKUP($B48,INDIRECT("'" & K$2 & "'!$C$3:$R$100"),8,FALSE),"") | L48: =IFERROR(VLOOKUP($B48,INDIRECT("'" & L$2 & "'!$C$3:$R$100"),8,FALSE),"") -> 0 | ... AM48: =IFERROR(VLOOKUP($B48,INDIRECT("'" & AM$2 & "'!$C$3:$R$100"),8,FALSE),"") -> 0 | AN48: =AL48/SUM($AL$4:$AL$68) -> 0 | AO48: =Z48/R48-1 -> #DIV/0! | AP48: =AL48/AD48-1 -> #DIV/0! | AT48: =IFERROR(AJ48/$AJ$69,"") -> 0
A49: Foreign Banks | B49: BANK OF AMERICA | C49: =IFERROR(VLOOKUP(B49,'1'!$C$3:$S$100,8,FALSE),"") -> 22137 | D49: =IFERROR(VLOOKUP(B49,'2'!$C$3:$S$100,8,FALSE),"") -> 21955 | E49: =IFERROR(VLOOKUP($B49,INDIRECT("'" & E$2 & "'!$C$3:$R$100"),8,FALSE),"") -> 21756 | F49: =IFERROR(VLOOKUP($B49,INDIRECT("'" & F$2 & "'!$C$3:$R$100"),8,FALSE),"") -> 21588 | G49: =IFERROR(VLOOKUP($B49,INDIRECT("'" & G$2 & "'!$C$3:$R$100"),8,FALSE),"") -> 21417 | H49: =IFERROR(VLOOKUP($B49,INDIRECT("'" & H$2 & "'!$C$3:$R$100"),8,FALSE),"") -> 21274 | I49: =IFERROR(VLOOKUP($B49,INDIRECT("'" & I$2 & "'!$C$3:$R$100"),8,FALSE),"") -> 21092 | J49: =IFERROR(VLOOKUP($B49,INDIRECT("'" & J$2 & "'!$C$3:$R$100"),8,FALSE),"") -> 19589 | K49: =IFERROR(VLOOKUP($B49,INDIRECT("'" & K$2 & "'!$C$3:$R$100"),8,FALSE),"") -> 17930 | L49: =IFERROR(VLOOKUP($B49,INDIRECT("'" & L$2 & "'!$C$3:$R$100"),8,FALSE),"") -> 7241 | ... AM49: =IFERROR(VLOOKUP($B49,INDIRECT("'" & AM$2 & "'!$C$3:$R$100"),8,FALSE),"") -> 0 | AN49: =AL49/SUM($AL$4:$AL$68) -> 0 | AO49: =Z49/R49-1 -> #DIV/0! | AP49: =AL49/AD49-1 -> #DIV/0! | AT49: =IFERROR(AJ49/$AJ$69,"") -> 0
A50: Foreign Banks | B50: BANK OF BAHRAIN & KUWAIT B.S.C. | C50: =IFERROR(VLOOKUP(B50,'1'!$C$3:$S$100,8,FALSE),"") | D50: =IFERROR(VLOOKUP(B50,'2'!$C$3:$S$100,8,FALSE),"") | E50: =IFERROR(VLOOKUP($B50,INDIRECT("'" & E$2 & "'!$C$3:$R$100"),8,FALSE),"") | F50: =IFERROR(VLOOKUP($B50,INDIRECT("'" & F$2 & "'!$C$3:$R$100"),8,FALSE),"") | G50: =IFERROR(VLOOKUP($B50,INDIRECT("'" & G$2 & "'!$C$3:$R$100"),8,FALSE),"") | H50: =IFERROR(VLOOKUP($B50,INDIRECT("'" & H$2 & "'!$C$3:$R$100"),8,FALSE),"") | I50: =IFERROR(VLOOKUP($B50,INDIRECT("'" & I$2 & "'!$C$3:$R$100"),8,FALSE),"") | J50: =IFERROR(VLOOKUP($B50,INDIRECT("'" & J$2 & "'!$C$3:$R$100"),8,FALSE),"") | K50: =IFERROR(VLOOKUP($B50,INDIRECT("'" & K$2 & "'!$C$3:$R$100"),8,FALSE),"") | L50: =IFERROR(VLOOKUP($B50,INDIRECT("'" & L$2 & "'!$C$3:$R$100"),8,FALSE),"") | ... AM50: =IFERROR(VLOOKUP($B50,INDIRECT("'" & AM$2 & "'!$C$3:$R$100"),8,FALSE),"") -> 0 | AN50: =AL50/SUM($AL$4:$AL$68) -> 0 | AO50: =Z50/R50-1 -> #VALUE! | AP50: =AL50/AD50-1 -> #DIV/0! | AT50: =IFERROR(AJ50/$AJ$69,"") -> 0
A51: Foreign Banks | B51: BARCLAYS BANK PLC | C51: =IFERROR(VLOOKUP(B51,'1'!$C$3:$S$100,8,FALSE),"") -> 0 | D51: =IFERROR(VLOOKUP(B51,'2'!$C$3:$S$100,8,FALSE),"") -> 0 | E51: =IFERROR(VLOOKUP($B51,INDIRECT("'" & E$2 & "'!$C$3:$R$100"),8,FALSE),"") -> 0 | F51: =IFERROR(VLOOKUP($B51,INDIRECT("'" & F$2 & "'!$C$3:$R$100"),8,FALSE),"") -> 0 | G51: =IFERROR(VLOOKUP($B51,INDIRECT("'" & G$2 & "'!$C$3:$R$100"),8,FALSE),"") -> 0 | H51: =IFERROR(VLOOKUP($B51,INDIRECT("'" & H$2 & "'!$C$3:$R$100"),8,FALSE),"") -> 0 | I51: =IFERROR(VLOOKUP($B51,INDIRECT("'" & I$2 & "'!$C$3:$R$100"),8,FALSE),"") -> 0 | J51: =IFERROR(VLOOKUP($B51,INDIRECT("'" & J$2 & "'!$C$3:$R$100"),8,FALSE),"") -> 0 | K51: =IFERROR(VLOOKUP($B51,INDIRECT("'" & K$2 & "'!$C$3:$R$100"),8,FALSE),"") -> 0 | L51: =IFERROR(VLOOKUP($B51,INDIRECT("'" & L$2 & "'!$C$3:$R$100"),8,FALSE),"") -> 0 | ... AM51: =IFERROR(VLOOKUP($B51,INDIRECT("'" & AM$2 & "'!$C$3:$R$100"),8,FALSE),"") -> 0 | AN51: =AL51/SUM($AL$4:$AL$68) -> 0 | AO51: =Z51/R51-1 -> #DIV/0! | AP51: =AL51/AD51-1 -> #DIV/0! | AT51: =IFERROR(AJ51/$AJ$69,"") -> 0
A52: Foreign Banks | B52: DEUTSCHE BANK LTD | C52: =IFERROR(VLOOKUP(B52,'1'!$C$3:$S$100,8,FALSE),"") -> 0 | D52: =IFERROR(VLOOKUP(B52,'2'!$C$3:$S$100,8,FALSE),"") -> 0 | E52: =IFERROR(VLOOKUP($B52,INDIRECT("'" & E$2 & "'!$C$3:$R$100"),8,FALSE),"") -> 0 | F52: =IFERROR(VLOOKUP($B52,INDIRECT("'" & F$2 & "'!$C$3:$R$100"),8,FALSE),"") -> 0 | G52: =IFERROR(VLOOKUP($B52,INDIRECT("'" & G$2 & "'!$C$3:$R$100"),8,FALSE),"") -> 0 | H52: =IFERROR(VLOOKUP($B52,INDIRECT("'" & H$2 & "'!$C$3:$R$100"),8,FALSE),"") -> 0 | I52: =IFERROR(VLOOKUP($B52,INDIRECT("'" & I$2 & "'!$C$3:$R$100"),8,FALSE),"") -> 0 | J52: =IFERROR(VLOOKUP($B52,INDIRECT("'" & J$2 & "'!$C$3:$R$100"),8,FALSE),"") -> 0 | K52: =IFERROR(VLOOKUP($B52,INDIRECT("'" & K$2 & "'!$C$3:$R$100"),8,FALSE),"") -> 0 | L52: =IFERROR(VLOOKUP($B52,INDIRECT("'" & L$2 & "'!$C$3:$R$100"),8,FALSE),"") -> 0 | ... AM52: =IFERROR(VLOOKUP($B52,INDIRECT("'" & AM$2 & "'!$C$3:$R$100"),8,FALSE),"") -> 0 | AN52: =AL52/SUM($AL$4:$AL$68) -> 0 | AO52: =Z52/R52-1 -> #DIV/0! | AP52: =AL52/AD52-1 -> #DIV/0! | AT52: =IFERROR(AJ52/$AJ$69,"") -> 0
A53: Foreign Banks | B53: DOHA BANK Q.P.S.C. | C53: =IFERROR(VLOOKUP(B53,'1'!$C$3:$S$100,8,FALSE),"") | D53: =IFERROR(VLOOKUP(B53,'2'!$C$3:$S$100,8,FALSE),"") | E53: =IFERROR(VLOOKUP($B53,INDIRECT("'" & E$2 & "'!$C$3:$R$100"),8,FALSE),"") | F53: =IFERROR(VLOOKUP($B53,INDIRECT("'" & F$2 & "'!$C$3:$R$100"),8,FALSE),"") | G53: =IFERROR(VLOOKUP($B53,INDIRECT("'" & G$2 & "'!$C$3:$R$100"),8,FALSE),"") | H53: =IFERROR(VLOOKUP($B53,INDIRECT("'" & H$2 & "'!$C$3:$R$100"),8,FALSE),"") | I53: =IFERROR(VLOOKUP($B53,INDIRECT("'" & I$2 & "'!$C$3:$R$100"),8,FALSE),"") | J53: =IFERROR(VLOOKUP($B53,INDIRECT("'" & J$2 & "'!$C$3:$R$100"),8,FALSE),"") | K53: =IFERROR(VLOOKUP($B53,INDIRECT("'" & K$2 & "'!$C$3:$R$100"),8,FALSE),"") | L53: =IFERROR(VLOOKUP($B53,INDIRECT("'" & L$2 & "'!$C$3:$R$100"),8,FALSE),"") | ... AM53: =IFERROR(VLOOKUP($B53,INDIRECT("'" & AM$2 & "'!$C$3:$R$100"),8,FALSE),"") -> 0 | AN53: =AL53/SUM($AL$4:$AL$68) -> 0 | AO53: =Z53/R53-1 -> #VALUE! | AP53: =AL53/AD53-1 -> #DIV/0! | AT53: =IFERROR(AJ53/$AJ$69,"") -> 0
A54: Foreign Banks | B54: KEB HANA BANK | C54: =IFERROR(VLOOKUP(B54,'1'!$C$3:$S$100,8,FALSE),"") | D54: =IFERROR(VLOOKUP(B54,'2'!$C$3:$S$100,8,FALSE),"") | E54: =IFERROR(VLOOKUP($B54,INDIRECT("'" & E$2 & "'!$C$3:$R$100"),8,FALSE),"") | F54: =IFERROR(VLOOKUP($B54,INDIRECT("'" & F$2 & "'!$C$3:$R$100"),8,FALSE),"") | G54: =IFERROR(VLOOKUP($B54,INDIRECT("'" & G$2 & "'!$C$3:$R$100"),8,FALSE),"") | H54: =IFERROR(VLOOKUP($B54,INDIRECT("'" & H$2 & "'!$C$3:$R$100"),8,FALSE),"") | I54: =IFERROR(VLOOKUP($B54,INDIRECT("'" & I$2 & "'!$C$3:$R$100"),8,FALSE),"") | J54: =IFERROR(VLOOKUP($B54,INDIRECT("'" & J$2 & "'!$C$3:$R$100"),8,FALSE),"") | K54: =IFERROR(VLOOKUP($B54,INDIRECT("'" & K$2 & "'!$C$3:$R$100"),8,FALSE),"") | L54: =IFERROR(VLOOKUP($B54,INDIRECT("'" & L$2 & "'!$C$3:$R$100"),8,FALSE),"") | ... AM54: =IFERROR(VLOOKUP($B54,INDIRECT("'" & AM$2 & "'!$C$3:$R$100"),8,FALSE),"") -> 0 | AN54: =AL54/SUM($AL$4:$AL$68) -> 0 | AO54: =Z54/R54-1 -> #VALUE! | AP54: =AL54/AD54-1 -> #DIV/0! | AT54: =IFERROR(AJ54/$AJ$69,"") -> 0
... A68: Small Finance Banks | B68: UNITY SMALL FINANCE BANK LTD | C68: =IFERROR(VLOOKUP(B68,'1'!$C$3:$S$100,8,FALSE),"") -> 0 | D68: =IFERROR(VLOOKUP(B68,'2'!$C$3:$S$100,8,FALSE),"") -> 0 | E68: =IFERROR(VLOOKUP($B68,INDIRECT("'" & E$2 & "'!$C$3:$R$100"),8,FALSE),"") -> 0 | F68: =IFERROR(VLOOKUP($B68,INDIRECT("'" & F$2 & "'!$C$3:$R$100"),8,FALSE),"") -> 0 | G68: =IFERROR(VLOOKUP($B68,INDIRECT("'" & G$2 & "'!$C$3:$R$100"),8,FALSE),"") -> 0 | H68: =IFERROR(VLOOKUP($B68,INDIRECT("'" & H$2 & "'!$C$3:$R$100"),8,FALSE),"") -> 0 | I68: =IFERROR(VLOOKUP($B68,INDIRECT("'" & I$2 & "'!$C$3:$R$100"),8,FALSE),"") -> 0 | J68: =IFERROR(VLOOKUP($B68,INDIRECT("'" & J$2 & "'!$C$3:$R$100"),8,FALSE),"") -> 0 | K68: =IFERROR(VLOOKUP($B68,INDIRECT("'" & K$2 & "'!$C$3:$R$100"),8,FALSE),"") -> 0 | L68: =IFERROR(VLOOKUP($B68,INDIRECT("'" & L$2 & "'!$C$3:$R$100"),8,FALSE),"") -> 0 | ... AM68: =IFERROR(VLOOKUP($B68,INDIRECT("'" & AM$2 & "'!$C$3:$R$100"),8,FALSE),"") -> 0 | AN68: =AL68/SUM($AL$4:$AL$68) -> 0 | AO68: =Z68/R68-1 -> #DIV/0! | AP68: =AL68/AD68-1 -> #DIV/0! | AT68: =IFERROR(AJ68/$AJ$69,"") -> 0
B69: Total | C69: =SUM(C4:C68) -> 70252069 | D69: =SUM(D4:D68) -> 71707614 | E69: =SUM(E4:E68) -> 73627330 | F69: =SUM(F4:F68) -> 75166069 | G69: =SUM(G4:G68) -> 76876980 | H69: =SUM(H4:H68) -> 78722617 | I69: =SUM(I4:I68) -> 80255722 | J69: =SUM(J4:J68) -> 77991469 | ... AM69: =SUM(AM4:AM68) -> 108873184 | AN69: =AL69/SUM($AL$4:$AL$68) -> 1
AM70: =AM69+'Summary DC Vol'!AM69 -> 1090912461
C73: 21 | D73: =C73+3 -> 24 | E73: =D73+3 -> 27 | F73: =E73+3 -> 30 | G73: =F73+3 -> 33 | H73: =G73+3 -> 36
A74: S. No | B74: Credit Card Outstanding (Crores) | C74: 45170 | D74: 45261 | E74: 45352 | F74: 45444 | G74: 45536 | H74: 45627 | I74: % Total as of Dec 24 | J74: 12M Growth %
A75: 1 | B75: HDFC BANK LTD | C75: =VLOOKUP($B75,$B$2:$AL$69,C$73,FALSE)/10^7 -> 1.8533409 | D75: =VLOOKUP($B75,$B$2:$AL$69,D$73,FALSE)/10^7 -> 1.951214 | E75: =VLOOKUP($B75,$B$2:$AL$69,E$73,FALSE)/10^7 -> 2.0404625 | F75: =VLOOKUP($B75,$B$2:$AL$69,F$73,FALSE)/10^7 -> 2.1111287 | G75: =VLOOKUP($B75,$B$2:$AL$69,G$73,FALSE)/10^7 -> 2.1973579 | H75: =VLOOKUP($B75,$B$2:$AL$69,H$73,FALSE)/10^7 -> 2.2833425 | I75: =H75/$H$97 -> 0.2129195 | J75: =H75/D75-1 -> 0.17021634 | K75: =H75/E75-1 -> 0.11903184
A76: 2 | B76: STATE BANK OF INDIA | C76: =VLOOKUP($B76,$B$2:$AL$69,C$73,FALSE)/10^7 -> 1.7779055 | D76: =VLOOKUP($B76,$B$2:$AL$69,D$73,FALSE)/10^7 -> 1.8251184 | E76: =VLOOKUP($B76,$B$2:$AL$69,E$73,FALSE)/10^7 -> 1.8751636 | F76: =VLOOKUP($B76,$B$2:$AL$69,F$73,FALSE)/10^7 -> 1.9117365 | G76: =VLOOKUP($B76,$B$2:$AL$69,G$73,FALSE)/10^7 -> 1.9447459 | H76: =VLOOKUP($B76,$B$2:$AL$69,H$73,FALSE)/10^7 -> 2.0038207 | I76: =H76/$H$97 -> 0.18685436 | J76: =H76/D76-1 -> 0.097912716 | K76: =H76/E76-1 -> 0.068611133
A77: 3 | B77: ICICI BANK LTD | C77: =VLOOKUP($B77,$B$2:$AL$69,C$73,FALSE)/10^7 -> 1.5298217 | D77: =VLOOKUP($B77,$B$2:$AL$69,D$73,FALSE)/10^7 -> 1.6206426 | E77: =VLOOKUP($B77,$B$2:$AL$69,E$73,FALSE)/10^7 -> 1.6846344 | F77: =VLOOKUP($B77,$B$2:$AL$69,F$73,FALSE)/10^7 -> 1.7084977 | G77: =VLOOKUP($B77,$B$2:$AL$69,G$73,FALSE)/10^7 -> 1.7558265 | H77: =VLOOKUP($B77,$B$2:$AL$69,H$73,FALSE)/10^7 -> 1.7751518 | I77: =H77/$H$97 -> 0.1655312 | J77: =H77/D77-1 -> 0.095338232 | K77: =H77/E77-1 -> 0.053731183
A78: 4 | B78: AXIS BANK LTD | C78: =VLOOKUP($B78,$B$2:$AL$69,C$73,FALSE)/10^7 -> 1.2959431 | D78: =VLOOKUP($B78,$B$2:$AL$69,D$73,FALSE)/10^7 -> 1.343747 | E78: =VLOOKUP($B78,$B$2:$AL$69,E$73,FALSE)/10^7 -> 1.3909552 | F78: =VLOOKUP($B78,$B$2:$AL$69,F$73,FALSE)/10^7 -> 1.4340543 | G78: =VLOOKUP($B78,$B$2:$AL$69,G$73,FALSE)/10^7 -> 1.4739214 | H78: =VLOOKUP($B78,$B$2:$AL$69,H$73,FALSE)/10^7 -> 1.4731919 | I78: =H78/$H$97 -> 0.13737373 | J78: =H78/D78-1 -> 0.096331303 | K78: =H78/E78-1 -> 0.059122465
A79: 5 | B79: RBL BANK LTD | C79: =VLOOKUP($B79,$B$2:$AL$69,C$73,FALSE)/10^7 -> 0.4715011 | D79: =VLOOKUP($B79,$B$2:$AL$69,D$73,FALSE)/10^7 -> 0.4944182 | E79: =VLOOKUP($B79,$B$2:$AL$69,E$73,FALSE)/10^7 -> 0.5161788 | F79: =VLOOKUP($B79,$B$2:$AL$69,F$73,FALSE)/10^7 -> 0.5232433 | G79: =VLOOKUP($B79,$B$2:$AL$69,G$73,FALSE)/10^7 -> 0.5264023 | H79: =VLOOKUP($B79,$B$2:$AL$69,H$73,FALSE)/10^7 -> 0.5108342 | I79: =H79/$H$97 -> 0.047634799 | J79: =H79/D79-1 -> 0.033202661 | K79: =H79/E79-1 -> -0.010354164
A80: 6 | B80: KOTAK MAHINDRA BANK LTD | C80: =VLOOKUP($B80,$B$2:$AL$69,C$73,FALSE)/10^7 -> 0.5399623 | D80: =VLOOKUP($B80,$B$2:$AL$69,D$73,FALSE)/10^7 -> 0.5666441 | E80: =VLOOKUP($B80,$B$2:$AL$69,E$73,FALSE)/10^7 -> 0.6042418 | F80: =VLOOKUP($B80,$B$2:$AL$69,F$73,FALSE)/10^7 -> 0.5935815 | G80: =VLOOKUP($B80,$B$2:$AL$69,G$73,FALSE)/10^7 -> 0.5413306 | H80: =VLOOKUP($B80,$B$2:$AL$69,H$73,FALSE)/10^7 -> 0.5094515 | I80: =H80/$H$97 -> 0.047505863 | J80: =H80/D80-1 -> -0.10093214 | K80: =H80/E80-1 -> -0.15687478
A81: 7 | B81: IDFC FIRST BANK LTD | C81: =VLOOKUP($B81,$B$2:$AL$69,C$73,FALSE)/10^7 -> 0.181903 | D81: =VLOOKUP($B81,$B$2:$AL$69,D$73,FALSE)/10^7 -> 0.2116838 | E81: =VLOOKUP($B81,$B$2:$AL$69,E$73,FALSE)/10^7 -> 0.2436772 | F81: =VLOOKUP($B81,$B$2:$AL$69,F$73,FALSE)/10^7 -> 0.2743113 | G81: =VLOOKUP($B81,$B$2:$AL$69,G$73,FALSE)/10^7 -> 0.297443 | H81: =VLOOKUP($B81,$B$2:$AL$69,H$73,FALSE)/10^7 -> 0.321185 | I81: =H81/$H$97 -> 0.029950193 | J81: =H81/D81-1 -> 0.51728663 | K81: =H81/E81-1 -> 0.31807572
...

Sheet Summary DC Vol
B2: Sheet Name | C2: 1 | D2: =C2+1 -> 2 | E2: =D2+1 -> 3 | F2: =E2+1 -> 4 | G2: =F2+1 -> 5 | H2: =G2+1 -> 6 | I2: =H2+1 -> 7 | J2: =I2+1 -> 8 | K2: =J2+1 -> 9 | ... AM2: =AL2+1 -> 37
B3: Months | C3: 44562 | D3: =EOMONTH(C3,1)-1 -> 44619 | E3: =EOMONTH(D3,1)-1 -> 44650 | F3: =EOMONTH(E3,1)-1 -> 44680 | G3: =EOMONTH(F3,1)-1 -> 44711 | H3: =EOMONTH(G3,1)-1 -> 44741 | I3: =EOMONTH(H3,1)-1 -> 44772 | J3: =EOMONTH(I3,1)-1 -> 44803 | K3: =EOMONTH(J3,1)-1 -> 44833 | ... AM3: =EOMONTH(AL3,1)-1 -> 45687 | AO3: FY 24 9M | AP3: FY 25 9 M | AT3: % distribution of Total
A4: Scheduled Commercial Banks | B4: STATE BANK OF INDIA | C4: =IFERROR(VLOOKUP(B4,'1'!$C$3:$S$100,13,FALSE),"") -> 280953089 | D4: =IFERROR(VLOOKUP(B4,'2'!$C$3:$S$100,13,FALSE),"") -> 275398132 | E4: =IFERROR(VLOOKUP($B4,INDIRECT("'" & E$2 & "'!$C$3:$R$100"),9,FALSE),"") -> 275922932 | F4: =IFERROR(VLOOKUP($B4,INDIRECT("'" & F$2 & "'!$C$3:$R$100"),9,FALSE),"") -> 279530049 | G4: =IFERROR(VLOOKUP($B4,INDIRECT("'" & G$2 & "'!$C$3:$R$100"),9,FALSE),"") -> 278381730 | H4: =IFERROR(VLOOKUP($B4,INDIRECT("'" & H$2 & "'!$C$3:$R$100"),9,FALSE),"") -> 274069731 | I4: =IFERROR(VLOOKUP($B4,INDIRECT("'" & I$2 & "'!$C$3:$R$100"),9,FALSE),"") -> 274637296 | J4: =IFERROR(VLOOKUP($B4,INDIRECT("'" & J$2 & "'!$C$3:$R$100"),9,FALSE),"") -> 277159959 | K4: =IFERROR(VLOOKUP($B4,INDIRECT("'" & K$2 & "'!$C$3:$R$100"),9,FALSE),"") -> 275397426 | L4: =IFERROR(VLOOKUP($B4,INDIRECT("'" & L$2 & "'!$C$3:$R$100"),9,FALSE),"") -> 277289229 | ... AM4: =IFERROR(VLOOKUP($B4,INDIRECT("'" & AM$2 & "'!$C$3:$R$100"),9,FALSE),"") -> 237986554 | AN4: =AL4/SUM($AL$4:$AL$68) -> 0.24251049 | AO4: =Z4/R4-1 -> -0.17248571 | AP4: =AL4/AD4-1 -> 0.048509875 | AT4: =IFERROR(AJ4/#REF!,"")
A5: Scheduled Commercial Banks | B5: BANK OF BARODA | C5: =IFERROR(VLOOKUP(B5,'1'!$C$3:$S$100,13,FALSE),"") -> 73809630 | D5: =IFERROR(VLOOKUP(B5,'2'!$C$3:$S$100,13,FALSE),"") -> 74000676 | E5: =IFERROR(VLOOKUP($B5,INDIRECT("'" & E$2 & "'!$C$3:$R$100"),9,FALSE),"") -> 74522207 | F5: =IFERROR(VLOOKUP($B5,INDIRECT("'" & F$2 & "'!$C$3:$R$100"),9,FALSE),"") -> 75272375 | G5: =IFERROR(VLOOKUP($B5,INDIRECT("'" & G$2 & "'!$C$3:$R$100"),9,FALSE),"") -> 75630687 | H5: =IFERROR(VLOOKUP($B5,INDIRECT("'" & H$2 & "'!$C$3:$R$100"),9,FALSE),"") -> 75993816 | I5: =IFERROR(VLOOKUP($B5,INDIRECT("'" & I$2 & "'!$C$3:$R$100"),9,FALSE),"") -> 76491940 | J5: =IFERROR(VLOOKUP($B5,INDIRECT("'" & J$2 & "'!$C$3:$R$100"),9,FALSE),"") -> 76893503 | K5: =IFERROR(VLOOKUP($B5,INDIRECT("'" & K$2 & "'!$C$3:$R$100"),9,FALSE),"") -> 77708499 | L5: =IFERROR(VLOOKUP($B5,INDIRECT("'" & L$2 & "'!$C$3:$R$100"),9,FALSE),"") -> 78440427 | ... AM5: =IFERROR(VLOOKUP($B5,INDIRECT("'" & AM$2 & "'!$C$3:$R$100"),9,FALSE),"") -> 87899577 | AN5: =AL5/SUM($AL$4:$AL$68) -> 0.088132805 | AO5: =Z5/R5-1 -> 0.12244438 | AP5: =AL5/AD5-1 -> -0.08835779 | AT5: =IFERROR(AJ5/#REF!,"")
A6: Scheduled Commercial Banks | B6: UNION BANK OF INDIA | C6: =IFERROR(VLOOKUP(B6,'1'!$C$3:$S$100,13,FALSE),"") -> 46993660 | D6: =IFERROR(VLOOKUP(B6,'2'!$C$3:$S$100,13,FALSE),"") -> 47410781 | E6: =IFERROR(VLOOKUP($B6,INDIRECT("'" & E$2 & "'!$C$3:$R$100"),9,FALSE),"") -> 47932253 | F6: =IFERROR(VLOOKUP($B6,INDIRECT("'" & F$2 & "'!$C$3:$R$100"),9,FALSE),"") -> 48242120 | G6: =IFERROR(VLOOKUP($B6,INDIRECT("'" & G$2 & "'!$C$3:$R$100"),9,FALSE),"") -> 48623903 | H6: =IFERROR(VLOOKUP($B6,INDIRECT("'" & H$2 & "'!$C$3:$R$100"),9,FALSE),"") -> 49044522 | I6: =IFERROR(VLOOKUP($B6,INDIRECT("'" & I$2 & "'!$C$3:$R$100"),9,FALSE),"") -> 49339980 | J6: =IFERROR(VLOOKUP($B6,INDIRECT("'" & J$2 & "'!$C$3:$R$100"),9,FALSE),"") -> 49647373 | K6: =IFERROR(VLOOKUP($B6,INDIRECT("'" & K$2 & "'!$C$3:$R$100"),9,FALSE),"") -> 50217508 | L6: =IFERROR(VLOOKUP($B6,INDIRECT("'" & L$2 & "'!$C$3:$R$100"),9,FALSE),"") -> 50324328 | ... AM6: =IFERROR(VLOOKUP($B6,INDIRECT("'" & AM$2 & "'!$C$3:$R$100"),9,FALSE),"") -> 55013536 | AN6: =AL6/SUM($AL$4:$AL$68) -> 0.061127873 | AO6: =Z6/R6-1 -> 0.059708514 | AP6: =AL6/AD6-1 -> 0.11223596 | AT6: =IFERROR(AJ6/#REF!,"")
A7: Scheduled Commercial Banks | B7: CANARA BANK | C7: =IFERROR(VLOOKUP(B7,'1'!$C$3:$S$100,13,FALSE),"") -> 45777153 | D7: =IFERROR(VLOOKUP(B7,'2'!$C$3:$S$100,13,FALSE),"") -> 46172471 | E7: =IFERROR(VLOOKUP($B7,INDIRECT("'" & E$2 & "'!$C$3:$R$100"),9,FALSE),"") -> 46459485 | F7: =IFERROR(VLOOKUP($B7,INDIRECT("'" & F$2 & "'!$C$3:$R$100"),9,FALSE),"") -> 47155319 | G7: =IFERROR(VLOOKUP($B7,INDIRECT("'" & G$2 & "'!$C$3:$R$100"),9,FALSE),"") -> 46959288 | H7: =IFERROR(VLOOKUP($B7,INDIRECT("'" & H$2 & "'!$C$3:$R$100"),9,FALSE),"") -> 46100836 | I7: =IFERROR(VLOOKUP($B7,INDIRECT("'" & I$2 & "'!$C$3:$R$100"),9,FALSE),"") -> 46819589 | J7: =IFERROR(VLOOKUP($B7,INDIRECT("'" & J$2 & "'!$C$3:$R$100"),9,FALSE),"") -> 47715491 | K7: =IFERROR(VLOOKUP($B7,INDIRECT("'" & K$2 & "'!$C$3:$R$100"),9,FALSE),"") -> 48539815 | L7: =IFERROR(VLOOKUP($B7,INDIRECT("'" & L$2 & "'!$C$3:$R$100"),9,FALSE),"") -> 47982447 | ... AM7: =IFERROR(VLOOKUP($B7,INDIRECT("'" & AM$2 & "'!$C$3:$R$100"),9,FALSE),"") -> 60036049 | AN7: =AL7/SUM($AL$4:$AL$68) -> 0.05993867 | AO7: =Z7/R7-1 -> 0.10358041 | AP7: =AL7/AD7-1 -> 0.031772959 | AT7: =IFERROR(AJ7/#REF!,"")
A8: Scheduled Commercial Banks | B8: HDFC BANK LTD | C8: =IFERROR(VLOOKUP(B8,'1'!$C$3:$S$100,13,FALSE),"") -> 41862466 | D8: =IFERROR(VLOOKUP(B8,'2'!$C$3:$S$100,13,FALSE),"") -> 42444090 | E8: =IFERROR(VLOOKUP($B8,INDIRECT("'" & E$2 & "'!$C$3:$R$100"),9,FALSE),"") -> 43041155 | F8: =IFERROR(VLOOKUP($B8,INDIRECT("'" & F$2 & "'!$C$3:$R$100"),9,FALSE),"") -> 43572256 | G8: =IFERROR(VLOOKUP($B8,INDIRECT("'" & G$2 & "'!$C$3:$R$100"),9,FALSE),"") -> 44236727 | H8: =IFERROR(VLOOKUP($B8,INDIRECT("'" & H$2 & "'!$C$3:$R$100"),9,FALSE),"") -> 45013206 | I8: =IFERROR(VLOOKUP($B8,INDIRECT("'" & I$2 & "'!$C$3:$R$100"),9,FALSE),"") -> 45803977 | J8: =IFERROR(VLOOKUP($B8,INDIRECT("'" & J$2 & "'!$C$3:$R$100"),9,FALSE),"") -> 46582533 | K8: =IFERROR(VLOOKUP($B8,INDIRECT("'" & K$2 & "'!$C$3:$R$100"),9,FALSE),"") -> 47410153 | L8: =IFERROR(VLOOKUP($B8,INDIRECT("'" & L$2 & "'!$C$3:$R$100"),9,FALSE),"") -> 48032697 | ... AM8: =IFERROR(VLOOKUP($B8,INDIRECT("'" & AM$2 & "'!$C$3:$R$100"),9,FALSE),"") -> 58648304 | AN8: =AL8/SUM($AL$4:$AL$68) -> 0.058928703 | AO8: =Z8/R8-1 -> 0.0431202 | AP8: =AL8/AD8-1 -> 0.054337657 | AT8: =IFERROR(AJ8/#REF!,"")
A9: Scheduled Commercial Banks | B9: PUNJAB NATIONAL BANK | C9: =IFERROR(VLOOKUP(B9,'1'!$C$3:$S$100,13,FALSE),"") -> 45514858 | D9: =IFERROR(VLOOKUP(B9,'2'!$C$3:$S$100,13,FALSE),"") -> 45773453 | E9: =IFERROR(VLOOKUP($B9,INDIRECT("'" & E$2 & "'!$C$3:$R$100"),9,FALSE),"") -> 45957631 | F9: =IFERROR(VLOOKUP($B9,INDIRECT("'" & F$2 & "'!$C$3:$R$100"),9,FALSE),"") -> 45677227 | G9: =IFERROR(VLOOKUP($B9,INDIRECT("'" & G$2 & "'!$C$3:$R$100"),9,FALSE),"") -> 45920571 | H9: =IFERROR(VLOOKUP($B9,INDIRECT("'" & H$2 & "'!$C$3:$R$100"),9,FALSE),"") -> 46296504 | I9: =IFERROR(VLOOKUP($B9,INDIRECT("'" & I$2 & "'!$C$3:$R$100"),9,FALSE),"") -> 46524689 | J9: =IFERROR(VLOOKUP($B9,INDIRECT("'" & J$2 & "'!$C$3:$R$100"),9,FALSE),"") -> 45499411 | K9: =IFERROR(VLOOKUP($B9,INDIRECT("'" & K$2 & "'!$C$3:$R$100"),9,FALSE),"") -> 45758496 | L9: =IFERROR(VLOOKUP($B9,INDIRECT("'" & L$2 & "'!$C$3:$R$100"),9,FALSE),"") -> 45911797 | ... AM9: =IFERROR(VLOOKUP($B9,INDIRECT("'" & AM$2 & "'!$C$3:$R$100"),9,FALSE),"") -> 41061227 | AN9: =AL9/SUM($AL$4:$AL$68) -> 0.041390002 | AO9: =Z9/R9-1 -> -0.021972637 | AP9: =AL9/AD9-1 -> 0.021991025 | AT9: =IFERROR(AJ9/#REF!,"")
A10: Scheduled Commercial Banks | B10: AXIS BANK LTD | C10: =IFERROR(VLOOKUP(B10,'1'!$C$3:$S$100,13,FALSE),"") -> 27077052 | D10: =IFERROR(VLOOKUP(B10,'2'!$C$3:$S$100,13,FALSE),"") -> 27314085 | E10: =IFERROR(VLOOKUP($B10,INDIRECT("'" & E$2 & "'!$C$3:$R$100"),9,FALSE),"") -> 27747647 | F10: =IFERROR(VLOOKUP($B10,INDIRECT("'" & F$2 & "'!$C$3:$R$100"),9,FALSE),"") -> 27912443 | G10: =IFERROR(VLOOKUP($B10,INDIRECT("'" & G$2 & "'!$C$3:$R$100"),9,FALSE),"") -> 28233123 | H10: =IFERROR(VLOOKUP($B10,INDIRECT("'" & H$2 & "'!$C$3:$R$100"),9,FALSE),"") -> 28729313 | I10: =IFERROR(VLOOKUP($B10,INDIRECT("'" & I$2 & "'!$C$3:$R$100"),9,FALSE),"") -> 29034253 | J10: =IFERROR(VLOOKUP($B10,INDIRECT("'" & J$2 & "'!$C$3:$R$100"),9,FALSE),"") -> 28975119 | K10: =IFERROR(VLOOKUP($B10,INDIRECT("'" & K$2 & "'!$C$3:$R$100"),9,FALSE),"") -> 28744562 | L10: =IFERROR(VLOOKUP($B10,INDIRECT("'" & L$2 & "'!$C$3:$R$100"),9,FALSE),"") -> 27975510 | ... AM10: =IFERROR(VLOOKUP($B10,INDIRECT("'" & AM$2 & "'!$C$3:$R$100"),9,FALSE),"") -> 39562869 | AN10: =AL10/SUM($AL$4:$AL$68) -> 0.039472305 | AO10: =Z10/R10-1 -> 0.12424807 | AP10: =AL10/AD10-1 -> 0.11346255 | AT10: =IFERROR(AJ10/#REF!,"")
A11: Scheduled Commercial Banks | B11: BANK OF INDIA | C11: =IFERROR(VLOOKUP(B11,'1'!$C$3:$S$100,13,FALSE),"") -> 44500508 | D11: =IFERROR(VLOOKUP(B11,'2'!$C$3:$S$100,13,FALSE),"") -> 44639149 | E11: =IFERROR(VLOOKUP($B11,INDIRECT("'" & E$2 & "'!$C$3:$R$100"),9,FALSE),"") -> 44856938 | F11: =IFERROR(VLOOKUP($B11,INDIRECT("'" & F$2 & "'!$C$3:$R$100"),9,FALSE),"") -> 44965718 | G11: =IFERROR(VLOOKUP($B11,INDIRECT("'" & G$2 & "'!$C$3:$R$100"),9,FALSE),"") -> 45256890 | H11: =IFERROR(VLOOKUP($B11,INDIRECT("'" & H$2 & "'!$C$3:$R$100"),9,FALSE),"") -> 45402570 | I11: =IFERROR(VLOOKUP($B11,INDIRECT("'" & I$2 & "'!$C$3:$R$100"),9,FALSE),"") -> 45431685 | J11: =IFERROR(VLOOKUP($B11,INDIRECT("'" & J$2 & "'!$C$3:$R$100"),9,FALSE),"") -> 45494860 | K11: =IFERROR(VLOOKUP($B11,INDIRECT("'" & K$2 & "'!$C$3:$R$100"),9,FALSE),"") -> 45593205 | L11: =IFERROR(VLOOKUP($B11,INDIRECT("'" & L$2 & "'!$C$3:$R$100"),9,FALSE),"") -> 45831608 | ... AM11: =IFERROR(VLOOKUP($B11,INDIRECT("'" & AM$2 & "'!$C$3:$R$100"),9,FALSE),"") -> 36546639 | AN11: =AL11/SUM($AL$4:$AL$68) -> 0.039101479 | AO11: =Z11/R11-1 -> -0.0024579687 | AP11: =AL11/AD11-1 -> -0.14106447 | AT11: =IFERROR(AJ11/#REF!,"")
A12: Scheduled Commercial Banks | B12: KOTAK MAHINDRA BANK LTD | C12: =IFERROR(VLOOKUP(B12,'1'!$C$3:$S$100,13,FALSE),"") -> 22536678 | D12: =IFERROR(VLOOKUP(B12,'2'!$C$3:$S$100,13,FALSE),"") -> 23059908 | E12: =IFERROR(VLOOKUP($B12,INDIRECT("'" & E$2 & "'!$C$3:$R$100"),9,FALSE),"") -> 23530754 | F12: =IFERROR(VLOOKUP($B12,INDIRECT("'" & F$2 & "'!$C$3:$R$100"),9,FALSE),"") -> 23883034 | G12: =IFERROR(VLOOKUP($B12,INDIRECT("'" & G$2 & "'!$C$3:$R$100"),9,FALSE),"") -> 24228289 | H12: =IFERROR(VLOOKUP($B12,INDIRECT("'" & H$2 & "'!$C$3:$R$100"),9,FALSE),"") -> 24587521 | I12: =IFERROR(VLOOKUP($B12,INDIRECT("'" & I$2 & "'!$C$3:$R$100"),9,FALSE),"") -> 24983429 | J12: =IFERROR(VLOOKUP($B12,INDIRECT("'" & J$2 & "'!$C$3:$R$100"),9,FALSE),"") -> 25526683 | K12: =IFERROR(VLOOKUP($B12,INDIRECT("'" & K$2 & "'!$C$3:$R$100"),9,FALSE),"") -> 25797993 | L12: =IFERROR(VLOOKUP($B12,INDIRECT("'" & L$2 & "'!$C$3:$R$100"),9,FALSE),"") -> 26089134 | ... AM12: =IFERROR(VLOOKUP($B12,INDIRECT("'" & AM$2 & "'!$C$3:$R$100"),9,FALSE),"") -> 34856978 | AN12: =AL12/SUM($AL$4:$AL$68) -> 0.035011375 | AO12: =Z12/R12-1 -> 0.13150112 | AP12: =AL12/AD12-1 -> 0.002512374 | AT12: =IFERROR(AJ12/#REF!,"")
A13: Scheduled Commercial Banks | B13: INDIAN BANK | C13: =IFERROR(VLOOKUP(B13,'1'!$C$3:$S$100,13,FALSE),"") -> 26592618 | D13: =IFERROR(VLOOKUP(B13,'2'!$C$3:$S$100,13,FALSE),"") -> 26745992 | E13: =IFERROR(VLOOKUP($B13,INDIRECT("'" & E$2 & "'!$C$3:$R$100"),9,FALSE),"") -> 26961021 | F13: =IFERROR(VLOOKUP($B13,INDIRECT("'" & F$2 & "'!$C$3:$R$100"),9,FALSE),"") -> 27095159 | G13: =IFERROR(VLOOKUP($B13,INDIRECT("'" & G$2 & "'!$C$3:$R$100"),9,FALSE),"") -> 27241274 | H13: =IFERROR(VLOOKUP($B13,INDIRECT("'" & H$2 & "'!$C$3:$R$100"),9,FALSE),"") -> 27703669 | I13: =IFERROR(VLOOKUP($B13,INDIRECT("'" & I$2 & "'!$C$3:$R$100"),9,FALSE),"") -> 28168095 | J13: =IFERROR(VLOOKUP($B13,INDIRECT("'" & J$2 & "'!$C$3:$R$100"),9,FALSE),"") -> 28371703 | K13: =IFERROR(VLOOKUP($B13,INDIRECT("'" & K$2 & "'!$C$3:$R$100"),9,FALSE),"") -> 28656557 | L13: =IFERROR(VLOOKUP($B13,INDIRECT("'" & L$2 & "'!$C$3:$R$100"),9,FALSE),"") -> 28816092 | ... AM13: =IFERROR(VLOOKUP($B13,INDIRECT("'" & AM$2 & "'!$C$3:$R$100"),9,FALSE),"") -> 33140182 | AN13: =AL13/SUM($AL$4:$AL$68) -> 0.033322383 | AO13: =Z13/R13-1 -> 0.0095639126 | AP13: =AL13/AD13-1 -> 0.022653363 | AT13: =IFERROR(AJ13/#REF!,"")
A14: Scheduled Commercial Banks | B14: ICICI BANK LTD | C14: =IFERROR(VLOOKUP(B14,'1'!$C$3:$S$100,13,FALSE),"") -> 36787344 | D14: =IFERROR(VLOOKUP(B14,'2'!$C$3:$S$100,13,FALSE),"") -> 36654493 | E14: =IFERROR(VLOOKUP($B14,INDIRECT("'" & E$2 & "'!$C$3:$R$100"),9,FALSE),"") -> 36655920 | F14: =IFERROR(VLOOKUP($B14,INDIRECT("'" & F$2 & "'!$C$3:$R$100"),9,FALSE),"") -> 36751248 | G14: =IFERROR(VLOOKUP($B14,INDIRECT("'" & G$2 & "'!$C$3:$R$100"),9,FALSE),"") -> 36983226 | H14: =IFERROR(VLOOKUP($B14,INDIRECT("'" & H$2 & "'!$C$3:$R$100"),9,FALSE),"") -> 36545077 | I14: =IFERROR(VLOOKUP($B14,INDIRECT("'" & I$2 & "'!$C$3:$R$100"),9,FALSE),"") -> 35712273 | J14: =IFERROR(VLOOKUP($B14,INDIRECT("'" & J$2 & "'!$C$3:$R$100"),9,FALSE),"") -> 35594187 | K14: =IFERROR(VLOOKUP($B14,INDIRECT("'" & K$2 & "'!$C$3:$R$100"),9,FALSE),"") -> 35633467 | L14: =IFERROR(VLOOKUP($B14,INDIRECT("'" & L$2 & "'!$C$3:$R$100"),9,FALSE),"") -> 35709144 | ... AM14: =IFERROR(VLOOKUP($B14,INDIRECT("'" & AM$2 & "'!$C$3:$R$100"),9,FALSE),"") -> 31847642 | AN14: =AL14/SUM($AL$4:$AL$68) -> 0.032110262 | AO14: =Z14/R14-1 -> -0.0037752462 | AP14: =AL14/AD14-1 -> -0.012327775 | AT14: =IFERROR(AJ14/#REF!,"")
A15: Scheduled Commercial Banks | B15: PAYTM PAYMENTS BANK | C15: =IFERROR(VLOOKUP(B15,'1'!$C$3:$S$100,13,FALSE),"") -> 66171234 | D15: =IFERROR(VLOOKUP(B15,'2'!$C$3:$S$100,13,FALSE),"") -> 61140286 | E15: =IFERROR(VLOOKUP($B15,INDIRECT("'" & E$2 & "'!$C$3:$R$100"),9,FALSE),"") -> 36619887 | F15: =IFERROR(VLOOKUP($B15,INDIRECT("'" & F$2 & "'!$C$3:$R$100"),9,FALSE),"") -> 36856402 | G15: =IFERROR(VLOOKUP($B15,INDIRECT("'" & G$2 & "'!$C$3:$R$100"),9,FALSE),"") -> 37013451 | H15: =IFERROR(VLOOKUP($B15,INDIRECT("'" & H$2 & "'!$C$3:$R$100"),9,FALSE),"") -> 37239918 | I15: =IFERROR(VLOOKUP($B15,INDIRECT("'" & I$2 & "'!$C$3:$R$100"),9,FALSE),"") -> 38074943 | J15: =IFERROR(VLOOKUP($B15,INDIRECT("'" & J$2 & "'!$C$3:$R$100"),9,FALSE),"") -> 37559643 | K15: =IFERROR(VLOOKUP($B15,INDIRECT("'" & K$2 & "'!$C$3:$R$100"),9,FALSE),"") -> 37703540 | L15: =IFERROR(VLOOKUP($B15,INDIRECT("'" & L$2 & "'!$C$3:$R$100"),9,FALSE),"") -> 37800341 | ... AM15: =IFERROR(VLOOKUP($B15,INDIRECT("'" & AM$2 & "'!$C$3:$R$100"),9,FALSE),"") -> 30602679 | AN15: =AL15/SUM($AL$4:$AL$68) -> 0.030884844 | AO15: =Z15/R15-1 -> -0.15041361 | AP15: =AL15/AD15-1 -> -0.052036281 | AT15: =IFERROR(AJ15/#REF!,"")
... A64: Small Finance Banks | B64: KOOKMIN BANK | C64: =IFERROR(VLOOKUP(B64,'1'!$C$3:$S$100,13,FALSE),"") | D64: =IFERROR(VLOOKUP(B64,'2'!$C$3:$S$100,13,FALSE),"") | E64: =IFERROR(VLOOKUP($B64,INDIRECT("'" & E$2 & "'!$C$3:$R$100"),9,FALSE),"") | F64: =IFERROR(VLOOKUP($B64,INDIRECT("'" & F$2 & "'!$C$3:$R$100"),9,FALSE),"") | G64: =IFERROR(VLOOKUP($B64,INDIRECT("'" & G$2 & "'!$C$3:$R$100"),9,FALSE),"") | H64: =IFERROR(VLOOKUP($B64,INDIRECT("'" & H$2 & "'!$C$3:$R$100"),9,FALSE),"") | I64: =IFERROR(VLOOKUP($B64,INDIRECT("'" & I$2 & "'!$C$3:$R$100"),9,FALSE),"") | J64: =IFERROR(VLOOKUP($B64,INDIRECT("'" & J$2 & "'!$C$3:$R$100"),9,FALSE),"") | K64: =IFERROR(VLOOKUP($B64,INDIRECT("'" & K$2 & "'!$C$3:$R$100"),9,FALSE),"") | L64: =IFERROR(VLOOKUP($B64,INDIRECT("'" & L$2 & "'!$C$3:$R$100"),9,FALSE),"") | ... AM64: =IFERROR(VLOOKUP($B64,INDIRECT("'" & AM$2 & "'!$C$3:$R$100"),9,FALSE),"") -> 493 | AN64: =AL64/SUM($AL$4:$AL$68) -> 4.8539376e-07 | AO64: =Z64/R64-1 -> #VALUE! | AP64: =AL64/AD64-1 -> 0.26912929 | AT64: =IFERROR(AJ64/#REF!,"")
A65: Small Finance Banks | B65: FINCARE SMALL FINANCE BANK LIMITED | C65: =IFERROR(VLOOKUP(B65,'1'!$C$3:$S$100,13,FALSE),0) -> 3123063 | D65: =IFERROR(VLOOKUP(C65,'1'!$C$3:$S$100,13,FALSE),0) -> 0 | E65: =IFERROR(VLOOKUP(D65,'1'!$C$3:$S$100,13,FALSE),0) -> 0 | F65: =IFERROR(VLOOKUP(E65,'1'!$C$3:$S$100,13,FALSE),0) -> 0 | G65: =IFERROR(VLOOKUP(F65,'1'!$C$3:$S$100,13,FALSE),0) -> 0 | H65: =IFERROR(VLOOKUP(G65,'1'!$C$3:$S$100,13,FALSE),0) -> 0 | I65: =IFERROR(VLOOKUP(H65,'1'!$C$3:$S$100,13,FALSE),0) -> 0 | J65: =IFERROR(VLOOKUP(I65,'1'!$C$3:$S$100,13,FALSE),0) -> 0 | ... AM65: =IFERROR(VLOOKUP(AL65,'1'!$C$3:$S$100,13,FALSE),0) -> 0 | AN65: =AL65/SUM($AL$4:$AL$68) -> 0 | AO65: =Z65/R65-1 -> #DIV/0! | AP65: =AL65/AD65-1 -> #DIV/0! | AT65: =IFERROR(AJ65/#REF!,"")
A66: Small Finance Banks | B66: AMERICAN EXPRESS BANKING CORPORATION | C66: =IFERROR(VLOOKUP(B66,'1'!$C$3:$S$100,13,FALSE),"") -> 0 | D66: =IFERROR(VLOOKUP(B66,'2'!$C$3:$S$100,13,FALSE),"") -> 0 | E66: =IFERROR(VLOOKUP($B66,INDIRECT("'" & E$2 & "'!$C$3:$R$100"),9,FALSE),"") -> 0 | F66: =IFERROR(VLOOKUP($B66,INDIRECT("'" & F$2 & "'!$C$3:$R$100"),9,FALSE),"") -> 0 | G66: =IFERROR(VLOOKUP($B66,INDIRECT("'" & G$2 & "'!$C$3:$R$100"),9,FALSE),"") -> 0 | H66: =IFERROR(VLOOKUP($B66,INDIRECT("'" & H$2 & "'!$C$3:$R$100"),9,FALSE),"") -> 0 | I66: =IFERROR(VLOOKUP($B66,INDIRECT("'" & I$2 & "'!$C$3:$R$100"),9,FALSE),"") -> 0 | J66: =IFERROR(VLOOKUP($B66,INDIRECT("'" & J$2 & "'!$C$3:$R$100"),9,FALSE),"") -> 0 | K66: =IFERROR(VLOOKUP($B66,INDIRECT("'" & K$2 & "'!$C$3:$R$100"),9,FALSE),"") -> 0 | L66: =IFERROR(VLOOKUP($B66,INDIRECT("'" & L$2 & "'!$C$3:$R$100"),9,FALSE),"") -> 0 | ... AM66: =IFERROR(VLOOKUP($B66,INDIRECT("'" & AM$2 & "'!$C$3:$R$100"),9,FALSE),"") -> 0 | AN66: =AL66/SUM($AL$4:$AL$68) -> 0 | AO66: =Z66/R66-1 -> #DIV/0! | AP66: =AL66/AD66-1 -> #DIV/0! | AT66: =IFERROR(AJ66/#REF!,"")
A67: Small Finance Banks | B67: BANK OF AMERICA | C67: =IFERROR(VLOOKUP(B67,'1'!$C$3:$S$100,13,FALSE),"") -> 0 | D67: =IFERROR(VLOOKUP(B67,'2'!$C$3:$S$100,13,FALSE),"") -> 0 | E67: =IFERROR(VLOOKUP($B67,INDIRECT("'" & E$2 & "'!$C$3:$R$100"),9,FALSE),"") -> 0 | F67: =IFERROR(VLOOKUP($B67,INDIRECT("'" & F$2 & "'!$C$3:$R$100"),9,FALSE),"") -> 0 | G67: =IFERROR(VLOOKUP($B67,INDIRECT("'" & G$2 & "'!$C$3:$R$100"),9,FALSE),"") -> 0 | H67: =IFERROR(VLOOKUP($B67,INDIRECT("'" & H$2 & "'!$C$3:$R$100"),9,FALSE),"") -> 0 | I67: =IFERROR(VLOOKUP($B67,INDIRECT("'" & I$2 & "'!$C$3:$R$100"),9,FALSE),"") -> 0 | J67: =IFERROR(VLOOKUP($B67,INDIRECT("'" & J$2 & "'!$C$3:$R$100"),9,FALSE),"") -> 0 | K67: =IFERROR(VLOOKUP($B67,INDIRECT("'" & K$2 & "'!$C$3:$R$100"),9,FALSE),"") -> 0 | L67: =IFERROR(VLOOKUP($B67,INDIRECT("'" & L$2 & "'!$C$3:$R$100"),9,FALSE),"") -> 0 | ... AM67: =IFERROR(VLOOKUP($B67,INDIRECT("'" & AM$2 & "'!$C$3:$R$100"),9,FALSE),"") -> 0 | AN67: =AL67/SUM($AL$4:$AL$68) -> 0 | AO67: =Z67/R67-1 -> #DIV/0! | AP67: =AL67/AD67-1 -> #DIV/0! | AT67: =IFERROR(AJ67/#REF!,"")
A68: Small Finance Banks | B68: CITI BANK | C68: =IFERROR(VLOOKUP(B68,'1'!$C$3:$S$100,13,FALSE),"") -> 1454747 | D68: =IFERROR(VLOOKUP(B68,'2'!$C$3:$S$100,13,FALSE),"") -> 1444035 | E68: =IFERROR(VLOOKUP($B68,INDIRECT("'" & E$2 & "'!$C$3:$R$100"),9,FALSE),"") -> 1432288 | F68: =IFERROR(VLOOKUP($B68,INDIRECT("'" & F$2 & "'!$C$3:$R$100"),9,FALSE),"") -> 1424091 | G68: =IFERROR(VLOOKUP($B68,INDIRECT("'" & G$2 & "'!$C$3:$R$100"),9,FALSE),"") -> 1343391 | H68: =IFERROR(VLOOKUP($B68,INDIRECT("'" & H$2 & "'!$C$3:$R$100"),9,FALSE),"") -> 1337043 | I68: =IFERROR(VLOOKUP($B68,INDIRECT("'" & I$2 & "'!$C$3:$R$100"),9,FALSE),"") -> 1333354 | J68: =IFERROR(VLOOKUP($B68,INDIRECT("'" & J$2 & "'!$C$3:$R$100"),9,FALSE),"") -> 1331815 | K68: =IFERROR(VLOOKUP($B68,INDIRECT("'" & K$2 & "'!$C$3:$R$100"),9,FALSE),"") -> 1319374 | L68: =IFERROR(VLOOKUP($B68,INDIRECT("'" & L$2 & "'!$C$3:$R$100"),9,FALSE),"") -> 1317002 | ... AM68: =IFERROR(VLOOKUP($B68,INDIRECT("'" & AM$2 & "'!$C$3:$R$100"),9,FALSE),"") -> 0 | AN68: =AL68/SUM($AL$4:$AL$68) -> 0 | AO68: =Z68/R68-1 -> #DIV/0! | AP68: =AL68/AD68-1 -> #DIV/0! | AT68: =IFERROR(AJ68/#REF!,"")
B69: Total | C69: =SUM(C4:C68) -> 940928583 | D69: =SUM(D4:D68) -> 931848434 | E69: =SUM(E4:E68) -> 914350747 | F69: =SUM(F4:F68) -> 916306086 | G69: =SUM(G4:G68) -> 914125576 | H69: =SUM(H4:H68) -> 911887550 | I69: =SUM(I4:I68) -> 924503198 | J69: =SUM(J4:J68) -> 931311729 | ... AM69: =SUM(AM4:AM68) -> 982039277
C73: 21 | D73: =C73+3 -> 24 | E73: =D73+3 -> 27 | F73: =E73+3 -> 30 | G73: =F73+3 -> 33 | H73: =G73+3 -> 36
A74: S. No | B74: Debit Card Outstanding (Crores) | C74: 45170 | D74: 45261 | E74: 45352 | F74: 45444 | G74: 45536 | H74: 45627 | I74: % Total as of Dec 24 | J74: 18M Growth %
A75: 1 | B75: STATE BANK OF INDIA | C75: =VLOOKUP($B75,$B$2:$AL$69,C$73,FALSE)/10^7 -> 26.141587 | D75: =VLOOKUP($B75,$B$2:$AL$69,D$73,FALSE)/10^7 -> 24.570687 | E75: =VLOOKUP($B75,$B$2:$AL$69,E$73,FALSE)/10^7 -> 22.787532 | F75: =VLOOKUP($B75,$B$2:$AL$69,F$73,FALSE)/10^7 -> 23.135083 | G75: =VLOOKUP($B75,$B$2:$AL$69,G$73,FALSE)/10^7 -> 23.392336 | H75: =VLOOKUP($B75,$B$2:$AL$69,H$73,FALSE)/10^7 -> 23.610437 | I75: =H75/$H$97 -> 0.24102815 | J75: =H75/C75-1 -> -0.096824668 | K75: =H75/E75-1 -> 0.036112063
A76: 2 | B76: BANK OF BARODA | C76: =VLOOKUP($B76,$B$2:$AL$69,C$73,FALSE)/10^7 -> 9.0550901 | D76: =VLOOKUP($B76,$B$2:$AL$69,D$73,FALSE)/10^7 -> 9.2992617 | E76: =VLOOKUP($B76,$B$2:$AL$69,E$73,FALSE)/10^7 -> 9.465817 | F76: =VLOOKUP($B76,$B$2:$AL$69,F$73,FALSE)/10^7 -> 9.6219184 | G76: =VLOOKUP($B76,$B$2:$AL$69,G$73,FALSE)/10^7 -> 9.8130715 | H76: =VLOOKUP($B76,$B$2:$AL$69,H$73,FALSE)/10^7 -> 8.6552638 | I76: =H76/$H$97 -> 0.088357628 | J76: =H76/C76-1 -> -0.044154867 | K76: =H76/E76-1 -> -0.085629502
A77: 3 | B77: UNION BANK OF INDIA | C77: =VLOOKUP($B77,$B$2:$AL$69,C$73,FALSE)/10^7 -> 5.242099 | D77: =VLOOKUP($B77,$B$2:$AL$69,D$73,FALSE)/10^7 -> 5.3584901 | E77: =VLOOKUP($B77,$B$2:$AL$69,E$73,FALSE)/10^7 -> 5.4243842 | F77: =VLOOKUP($B77,$B$2:$AL$69,F$73,FALSE)/10^7 -> 5.4841108 | G77: =VLOOKUP($B77,$B$2:$AL$69,G$73,FALSE)/10^7 -> 5.5908898 | H77: =VLOOKUP($B77,$B$2:$AL$69,H$73,FALSE)/10^7 -> 5.6625362 | I77: =H77/$H$97 -> 0.057806241 | J77: =H77/C77-1 -> 0.080203979 | K77: =H77/E77-1 -> 0.04390397
A78: 4 | B78: CANARA BANK | C78: =VLOOKUP($B78,$B$2:$AL$69,C$73,FALSE)/10^7 -> 5.3341318 | D78: =VLOOKUP($B78,$B$2:$AL$69,D$73,FALSE)/10^7 -> 5.6420528 | E78: =VLOOKUP($B78,$B$2:$AL$69,E$73,FALSE)/10^7 -> 5.7563848 | F78: =VLOOKUP($B78,$B$2:$AL$69,F$73,FALSE)/10^7 -> 5.7401577 | G78: =VLOOKUP($B78,$B$2:$AL$69,G$73,FALSE)/10^7 -> 5.8077451 | H78: =VLOOKUP($B78,$B$2:$AL$69,H$73,FALSE)/10^7 -> 5.9065159 | I78: =H78/$H$97 -> 0.060296919 | J78: =H78/C78-1 -> 0.10730595 | K78: =H78/E78-1 -> 0.026080796
A79: 5 | B79: HDFC BANK LTD | C79: =VLOOKUP($B79,$B$2:$AL$69,C$73,FALSE)/10^7 -> 5.1212603 | D79: =VLOOKUP($B79,$B$2:$AL$69,D$73,FALSE)/10^7 -> 5.2959912 | E79: =VLOOKUP($B79,$B$2:$AL$69,E$73,FALSE)/10^7 -> 5.4029646 | F79: =VLOOKUP($B79,$B$2:$AL$69,F$73,FALSE)/10^7 -> 5.591253 | G79: =VLOOKUP($B79,$B$2:$AL$69,G$73,FALSE)/10^7 -> 5.6795898 | H79: =VLOOKUP($B79,$B$2:$AL$69,H$73,FALSE)/10^7 -> 5.7889333 | I79: =H79/$H$97 -> 0.059096572 | J79: =H79/C79-1 -> 0.13037279 | K79: =H79/E79-1 -> 0.071436467
A80: 6 | B80: PUNJAB NATIONAL BANK | C80: =VLOOKUP($B80,$B$2:$AL$69,C$73,FALSE)/10^7 -> 4.1454165 | D80: =VLOOKUP($B80,$B$2:$AL$69,D$73,FALSE)/10^7 -> 4.0106166 | E80: =VLOOKUP($B80,$B$2:$AL$69,E$73,FALSE)/10^7 -> 3.9776588 | F80: =VLOOKUP($B80,$B$2:$AL$69,F$73,FALSE)/10^7 -> 4.0411045 | G80: =VLOOKUP($B80,$B$2:$AL$69,G$73,FALSE)/10^7 -> 4.0877319 | H80: =VLOOKUP($B80,$B$2:$AL$69,H$73,FALSE)/10^7 -> 4.0818142 | I80: =H80/$H$97 -> 0.041669374 | J80: =H80/C80-1 -> -0.015342801 | K80: =H80/E80-1 -> 0.026185102
A81: 7 | B81: AXIS BANK LTD | C81: =VLOOKUP($B81,$B$2:$AL$69,C$73,FALSE)/10^7 -> 3.2354482 | D81: =VLOOKUP($B81,$B$2:$AL$69,D$73,FALSE)/10^7 -> 3.372773 | E81: =VLOOKUP($B81,$B$2:$AL$69,E$73,FALSE)/10^7 -> 3.4214339 | F81: =VLOOKUP($B81,$B$2:$AL$69,F$73,FALSE)/10^7 -> 3.5813397 | G81: =VLOOKUP($B81,$B$2:$AL$69,G$73,FALSE)/10^7 -> 3.7304729 | H81: =VLOOKUP($B81,$B$2:$AL$69,H$73,FALSE)/10^7 -> 3.8956267 | I81: =H81/$H$97 -> 0.039768671 | J81: =H81/C81-1 -> 0.20404545 | K81: =H81/E81-1 -> 0.13859476
A82: 8 | B82: BANK OF INDIA | C82: =VLOOKUP($B82,$B$2:$AL$69,C$73,FALSE)/10^7 -> 4.9686011 | D82: =VLOOKUP($B82,$B$2:$AL$69,D$73,FALSE)/10^7 -> 4.8665137 | E82: =VLOOKUP($B82,$B$2:$AL$69,E$73,FALSE)/10^7 -> 4.6297797 | F82: =VLOOKUP($B82,$B$2:$AL$69,F$73,FALSE)/10^7 -> 4.4929324 | G82: =VLOOKUP($B82,$B$2:$AL$69,G$73,FALSE)/10^7 -> 4.0503878 | H82: =VLOOKUP($B82,$B$2:$AL$69,H$73,FALSE)/10^7 -> 3.9250483 | I82: =H82/$H$97 -> 0.040069022 | J82: =H82/C82-1 -> -0.2100295 | K82: =H82/E82-1 -> -0.15221705
A83: 9 | B83: KOTAK MAHINDRA BANK LTD | C83: =VLOOKUP($B83,$B$2:$AL$69,C$73,FALSE)/10^7 -> 3.0106574 | D83: =VLOOKUP($B83,$B$2:$AL$69,D$73,FALSE)/10^7 -> 3.1786794 | E83: =VLOOKUP($B83,$B$2:$AL$69,E$73,FALSE)/10^7 -> 3.3603903 | F83: =VLOOKUP($B83,$B$2:$AL$69,F$73,FALSE)/10^7 -> 3.446186 | G83: =VLOOKUP($B83,$B$2:$AL$69,G$73,FALSE)/10^7 -> 3.4536908 | H83: =VLOOKUP($B83,$B$2:$AL$69,H$73,FALSE)/10^7 -> 3.4856409 | I83: =H83/$H$97 -> 0.035583313 | J83: =H83/C83-1 -> 0.15776737 | K83: =H83/E83-1 -> 0.037272635
A84: 10 | B84: INDIAN BANK | C84: =VLOOKUP($B84,$B$2:$AL$69,C$73,FALSE)/10^7 -> 3.3122868 | D84: =VLOOKUP($B84,$B$2:$AL$69,D$73,FALSE)/10^7 -> 3.3303082 | E84: =VLOOKUP($B84,$B$2:$AL$69,E$73,FALSE)/10^7 -> 3.2243209 | F84: =VLOOKUP($B84,$B$2:$AL$69,F$73,FALSE)/10^7 -> 3.230257 | G84: =VLOOKUP($B84,$B$2:$AL$69,G$73,FALSE)/10^7 -> 3.2568181 | H84: =VLOOKUP($B84,$B$2:$AL$69,H$73,FALSE)/10^7 -> 3.2975066 | I84: =H84/$H$97 -> 0.033662736 | J84: =H84/C84-1 -> -0.0044622344 | K84: =H84/E84-1 -> 0.02269802
